Workbook

Sheet 20pdts2007
A1: beta-07 | B1: M1 | C1: M2 | D1: Q1 | E1: Q2 | F1: Q3 | G1: Q4 | H1: Q5 | J1: Elasticité-revenu 2007 | K1: M1 | L1: M2 | M1: Q1 | N1: Q2 | O1: Q3 | P1: Q4 | Q1: Q5 | S1: Elasticité-Prix 2007 | T1: M1 | U1: M2 | V1: Q1 | W1: Q2 | X1: Q3 | Y1: Q4 | Z1: Q5 | AB1: CB | AC1: M1 | AD1: M2 | AE1: Q1 | AF1: Q2 | AG1: Q3 | AH1: Q4 | AI1: Q5 | AJ1: CB-2007
A2: A00 | B2: 0.0820532 | C2: 0.1443764 | D2: 0.1737262 | E2: 0.1675444 | F2: 0.1276257 | G2: 0.1394096 | H2: 0.0621852 | J2: A00 | K2: =B2/AC2 -> 0.60469571 | L2: =C2/AD2 -> 0.86485086 | M2: =D2/AE2 -> 1.0594818 | N2: =E2/AF2 -> 1.0043047 | O2: =F2/AG2 -> 0.76665567 | P2: =G2/AH2 -> 0.8744419 | Q2: =H2/AI2 -> 0.50513122 | S2: A00 | T2: =IF(T24=0,0,((1-B2)*(K24/T24))-1) -> -0.6378944 | U2: =IF(U24=0,0,((1-C2)*(L24/U24))-1) -> -0.93109298 | V2: =IF(V24=0,0,((1-D2)*(M24/V24))-1) -> -1.0635157 | W2: =IF(W24=0,0,((1-E2)*(N24/W24))-1) -> -1.0236482 | X2: =IF(X24=0,0,((1-F2)*(O24/X24))-1) -> -0.84829327 | Y2: =IF(Y24=0,0,((1-G2)*(P24/Y24))-1) -> -0.92918623 | Z2: =IF(Z24=0,0,((1-H2)*(Q24/Z24))-1) -> -0.46800237 | AB2: A00 | AC2: 0.13569337 | AD2: 0.16693792 | AE2: 0.16397281 | AF2: 0.16682626 | AG2: 0.16647069 | AH2: 0.15942694 | AI2: 0.12310702 | AJ2: A00
A3: B05 | B3: 0.0121311 | C3: 0.0101907 | D3: 0.0167558 | E3: 0.0128859 | F3: 0.0145282 | G3: 0.0135288 | H3: 0.0109444 | J3: B05 | K3: =B3/AC3 -> 0.79672414 | L3: =C3/AD3 -> 0.90588147 | M3: =D3/AE3 -> 1.2082265 | N3: =E3/AF3 -> 0.91454487 | O3: =F3/AG3 -> 1.0165672 | P3: =G3/AH3 -> 0.91256775 | Q3: =H3/AI3 -> 0.80714419 | S3: B05 | T3: =IF(T25=0,0,((1-B3)*(K25/T25))-1) -> -0.80650356 | U3: =IF(U25=0,0,((1-C3)*(L25/U25))-1) -> -1.7090431 | V3: =IF(V25=0,0,((1-D3)*(M25/V25))-1) -> -1.4068859 | W3: =IF(W25=0,0,((1-E3)*(N25/W25))-1) -> -1.1973496 | X3: =IF(X25=0,0,((1-F3)*(O25/X25))-1) -> -1.6986777 | Y3: =IF(Y25=0,0,((1-G3)*(P25/Y25))-1) -> -1.3728091 | Z3: =IF(Z25=0,0,((1-H3)*(Q25/Z25))-1) -> -0.15907545 | AB3: B05 | AC3: 0.015226224 | AD3: 0.011249485 | AE3: 0.013868095 | AF3: 0.014089959 | AG3: 0.014291431 | AH3: 0.014824981 | AI3: 0.013559411 | AJ3: B05
A4: C00 | B4: 0.0001982 | C4: 0.0005578 | D4: 0.0009737 | E4: 0.0008139 | F4: 0.0006021 | G4: 0.0004611 | H4: 9.75e-05 | J4: C00 | K4: =B4/AC4 -> 0.35494691 | L4: =C4/AD4 -> 0.53344062 | M4: =D4/AE4 -> 0.90076311 | N4: =E4/AF4 -> 0.8008729 | O4: =F4/AG4 -> 0.65372805 | P4: =G4/AH4 -> 0.58068732 | Q4: =H4/AI4 -> 0.21217624 | S4: C00 | T4: =IF(T26=0,0,((1-B4)*(K26/T26))-1) -> -0.55686678 | U4: =IF(U26=0,0,((1-C4)*(L26/U26))-1) -> -9.2478947 | V4: =IF(V26=0,0,((1-D4)*(M26/V26))-1) -> -3.5359134 | W4: =IF(W26=0,0,((1-E4)*(N26/W26))-1) -> -4.7544032 | X4: =IF(X26=0,0,((1-F4)*(O26/X26))-1) -> -11.391573 | Y4: =IF(Y26=0,0,((1-G4)*(P26/Y26))-1) -> -9.2650108 | Z4: =IF(Z26=0,0,((1-H4)*(Q26/Z26))-1) -> 19.183367 | AB4: C00 | AC4: 0.00055839337 | AD4: 0.0010456647 | AE4: 0.0010809723 | AF4: 0.0010162661 | AG4: 0.00092102519 | AH4: 0.00079405901 | AI4: 0.00045952366 | AJ4: C00
A5: D01 | B5: 0.1009344 | C5: 0.2196602 | D5: 0.3334779 | E5: 0.3124982 | F5: 0.1863854 | G5: 0.2261472 | H5: 0.0612799 | J5: D01 | K5: =B5/AC5 -> 0.44734105 | L5: =C5/AD5 -> 0.66142194 | M5: =D5/AE5 -> 0.95310351 | N5: =E5/AF5 -> 0.92861148 | O5: =F5/AG5 -> 0.59394059 | P5: =G5/AH5 -> 0.78101543 | Q5: =H5/AI5 -> 0.32079717 | S5: D01 | T5: =IF(T27=0,0,((1-B5)*(K27/T27))-1) -> -0.50357252 | U5: =IF(U27=0,0,((1-C5)*(L27/U27))-1) -> -0.75721682 | V5: =IF(V27=0,0,((1-D5)*(M27/V27))-1) -> -0.97417384 | W5: =IF(W27=0,0,((1-E5)*(N27/W27))-1) -> -0.95913487 | X5: =IF(X27=0,0,((1-F5)*(O27/X27))-1) -> -0.69528037 | Y5: =IF(Y27=0,0,((1-G5)*(P27/Y27))-1) -> -0.84897587 | Z5: =IF(Z27=0,0,((1-H5)*(Q27/Z27))-1) -> -0.31861566 | AB5: D01 | AC5: 0.22563187 | AD5: 0.33210298 | AE5: 0.34988634 | AF5: 0.33652201 | AG5: 0.31381152 | AH5: 0.28955536 | AI5: 0.19102381 | AJ5: D01
A6: D02 | B6: 0.0453148 | C6: 0.0418716 | D6: 0.0393097 | E6: 0.0488253 | F6: 0.0433693 | G6: 0.0556264 | H6: 0.0411768 | J6: D02 | K6: =B6/AC6 -> 1.1283871 | L6: =C6/AD6 -> 1.1208592 | M6: =D6/AE6 -> 1.4951245 | N6: =E6/AF6 -> 1.5885187 | O6: =F6/AG6 -> 1.2502422 | P6: =G6/AH6 -> 1.3739846 | Q6: =H6/AI6 -> 0.92753509 | S6: D02 | T6: =IF(T28=0,0,((1-B6)*(K28/T28))-1) -> -1.1252485 | U6: =IF(U28=0,0,((1-C6)*(L28/U28))-1) -> -1.3496387 | V6: =IF(V28=0,0,((1-D6)*(M28/V28))-1) -> -1.5798406 | W6: =IF(W28=0,0,((1-E6)*(N28/W28))-1) -> -1.6842183 | X6: =IF(X28=0,0,((1-F6)*(O28/X28))-1) -> -1.5122862 | Y6: =IF(Y28=0,0,((1-G6)*(P28/Y28))-1) -> -1.5141049 | Z6: =IF(Z28=0,0,((1-H6)*(Q28/Z28))-1) -> -0.73800221 | AB6: D02 | AC6: 0.040158912 | AD6: 0.0373567 | AE6: 0.026291924 | AF6: 0.030736371 | AG6: 0.03468872 | AH6: 0.040485462 | AI6: 0.044393792 | AJ6: D02
A7: D03 | B7: 0.0269556 | C7: 0.0349151 | D7: 0.0473511 | E7: 0.0370152 | F7: 0.0524851 | G7: 0.0485892 | H7: 0.0195122 | J7: D03 | K7: =B7/AC7 -> 0.6264359 | L7: =C7/AD7 -> 0.87446462 | M7: =D7/AE7 -> 1.1507789 | N7: =E7/AF7 -> 0.80882062 | O7: =F7/AG7 -> 1.1343109 | P7: =G7/AH7 -> 1.0577608 | Q7: =H7/AI7 -> 0.51212139 | S7: D03 | T7: =IF(T29=0,0,((1-B7)*(K29/T29))-1) -> -0.63905515 | U7: =IF(U29=0,0,((1-C7)*(L29/U29))-1) -> -1.0992216 | V7: =IF(V29=0,0,((1-D7)*(M29/V29))-1) -> -1.2096503 | W7: =IF(W29=0,0,((1-E7)*(N29/W29))-1) -> -0.90050697 | X7: =IF(X29=0,0,((1-F7)*(O29/X29))-1) -> -1.3299005 | Y7: =IF(Y29=0,0,((1-G7)*(P29/Y29))-1) -> -1.1978416 | Z7: =IF(Z29=0,0,((1-H7)*(Q29/Z29))-1) -> -0.29225831 | AB7: D03 | AC7: 0.043030101 | AD7: 0.039927401 | AE7: 0.041146999 | AF7: 0.045764412 | AG7: 0.046270473 | AH7: 0.045935905 | AI7: 0.038100732 | AJ7: D03
A8: D04 | B8: 0.1445375 | C8: 0.0989986 | D8: 0.0330414 | E8: 0.0344071 | F8: 0.0557996 | G8: 0.0512764 | H8: 0.1825572 | J8: D04 | K8: =B8/AC8 -> 2.3757601 | L8: =C8/AD8 -> 2.2444593 | M8: =D8/AE8 -> 1.3373422 | N8: =E8/AF8 -> 1.2700428 | O8: =F8/AG8 -> 1.7316479 | P8: =G8/AH8 -> 1.4080487 | Q8: =H8/AI8 -> 2.1603917 | S8: D04 | T8: =IF(T30=0,0,((1-B8)*(K30/T30))-1) -> -2.1784965 | U8: =IF(U30=0,0,((1-C8)*(L30/U30))-1) -> -2.3074986 | V8: =IF(V30=0,0,((1-D8)*(M30/V30))-1) -> -1.4377822 | W8: =IF(W30=0,0,((1-E8)*(N30/W30))-1) -> -1.4040662 | X8: =IF(X30=0,0,((1-F8)*(O30/X30))-1) -> -1.9807798 | Y8: =IF(Y30=0,0,((1-G8)*(P30/Y30))-1) -> -1.5668546 | Z8: =IF(Z30=0,0,((1-H8)*(Q30/Z30))-1) -> -1.862326 | AB8: D04 | AC8: 0.060838423 | AD8: 0.044107995 | AE8: 0.024706765 | AF8: 0.027091292 | AG8: 0.032223409 | AH8: 0.036416638 | AI8: 0.0845019 | AJ8: D04
A9: D05 | B9: 0.0186356 | C9: 0.0152416 | D9: 0.0085444 | E9: 0.0113368 | F9: 0.0128215 | G9: 0.0159069 | H9: 0.0184083 | J9: D05 | K9: =B9/AC9 -> 1.5265996 | L9: =C9/AD9 -> 1.4186744 | M9: =D9/AE9 -> 1.3555845 | N9: =E9/AF9 -> 1.5692898 | O9: =F9/AG9 -> 1.5340399 | P9: =G9/AH9 -> 1.6085943 | Q9: =H9/AI9 -> 1.1701574 | S9: D05 | T9: =IF(T31=0,0,((1-B9)*(K31/T31))-1) -> -1.5258499 | U9: =IF(U31=0,0,((1-C9)*(L31/U31))-1) -> -2.2479886 | V9: =IF(V31=0,0,((1-D9)*(M31/V31))-1) -> -1.8010186 | W9: =IF(W31=0,0,((1-E9)*(N31/W31))-1) -> -2.1131271 | X9: =IF(X31=0,0,((1-F9)*(O31/X31))-1) -> -2.6959749 | Y9: =IF(Y31=0,0,((1-G9)*(P31/Y31))-1) -> -2.2854663 | Z9: =IF(Z31=0,0,((1-H9)*(Q31/Z31))-1) -> -0.61084769 | AB9: D05 | AC9: 0.012207261 | AD9: 0.01074355 | AE9: 0.0063031115 | AF9: 0.0072241597 | AG9: 0.0083579962 | AH9: 0.0098886959 | AI9: 0.015731473 | AJ9: D05
A10: D23 | B10: 0.0897724 | C10: 0.0687347 | D10: 0.0384991 | E10: 0.0339502 | F10: 0.0261937 | G10: 0.0353616 | H10: 0.1131543 | J10: D23 | K10: =B10/AC10 -> 1.7702043 | L10: =C10/AD10 -> 1.3733701 | M10: =D10/AE10 -> 0.7483696 | N10: =E10/AF10 -> 0.75027971 | O10: =F10/AG10 -> 0.62101114 | P10: =G10/AH10 -> 0.89022998 | Q10: =H10/AI10 -> 1.900521 | S10: D23 | T10: =IF(T32=0,0,((1-B10)*(K32/T32))-1) -> -1.7030854 | U10: =IF(U32=0,0,((1-C10)*(L32/U32))-1) -> -1.5173539 | V10: =IF(V32=0,0,((1-D10)*(M32/V32))-1) -> -0.81134677 | W10: =IF(W32=0,0,((1-E10)*(N32/W32))-1) -> -0.84460294 | X10: =IF(X32=0,0,((1-F10)*(O32/X32))-1) -> -0.85940123 | Y10: =IF(Y32=0,0,((1-G10)*(P32/Y32))-1) -> -1.0616508 | Z10: =IF(Z32=0,0,((1-H10)*(Q32/Z32))-1) -> -1.6658523 | AB10: D23 | AC10: 0.050713016 | AD10: 0.050048199 | AE10: 0.051443966 | AF10: 0.045250057 | AG10: 0.042179115 | AH10: 0.03972187 | AI10: 0.05953857 | AJ10: D23
A11: E00 | B11: 0.012832 | C11: 0.0219682 | D11: 0.042856 | E11: 0.033251 | F11: 0.0218009 | G11: 0.0235227 | H11: 0.0094612 | J11: E00 | K11: =B11/AC11 -> 0.38571931 | L11: =C11/AD11 -> 0.5106725 | M11: =D11/AE11 -> 0.7078317 | N11: =E11/AF11 -> 0.6434147 | O11: =F11/AG11 -> 0.48770699 | P11: =G11/AH11 -> 0.61225276 | Q11: =H11/AI11 -> 0.38028638 | S11: E00 | T11: =IF(T33=0,0,((1-B11)*(K33/T33))-1) -> -0.39694833 | U11: =IF(U33=0,0,((1-C11)*(L33/U33))-1) -> -0.72870622 | V11: =IF(V33=0,0,((1-D11)*(M33/V33))-1) -> -0.76542553 | W11: =IF(W33=0,0,((1-E11)*(N33/W33))-1) -> -0.73049058 | X11: =IF(X33=0,0,((1-F11)*(O33/X33))-1) -> -0.71542339 | Y11: =IF(Y33=0,0,((1-G11)*(P33/Y33))-1) -> -0.79671555 | Z11: =IF(Z33=0,0,((1-H11)*(Q33/Z33))-1) -> -0.031262916 | AB11: E00 | AC11: 0.033267715 | AD11: 0.043018177 | AE11: 0.060545466 | AF11: 0.051678956 | AG11: 0.044700815 | AH11: 0.038419917 | AI11: 0.024879145 | AJ11: E00
A12: F45 | B12: 0.0313006 | C12: 0.054291 | D12: 0.030967 | E12: 0.0463624 | F12: 0.0288599 | G12: 0.0175927 | H12: 0.0290268 | J12: F45 | K12: =B12/AC12 -> 1.3112558 | L12: =C12/AD12 -> 1.4765662 | M12: =D12/AE12 -> 1.6711537 | N12: =E12/AF12 -> 2.2300531 | O12: =F12/AG12 -> 1.2623007 | P12: =G12/AH12 -> 0.67152646 | Q12: =H12/AI12 -> 0.87165062 | S12: F45 | T12: =IF(T34=0,0,((1-B12)*(K34/T34))-1) -> -1.3060886 | U12: =IF(U34=0,0,((1-C12)*(L34/U34))-1) -> -1.6851956 | V12: =IF(V34=0,0,((1-D12)*(M34/V34))-1) -> -1.7994724 | W12: =IF(W34=0,0,((1-E12)*(N34/W34))-1) -> -2.3574664 | X12: =IF(X34=0,0,((1-F12)*(O34/X34))-1) -> -1.6750633 | Y12: =IF(Y34=0,0,((1-G12)*(P34/Y34))-1) -> -0.9360088 | Z12: =IF(Z34=0,0,((1-H12)*(Q34/Z34))-1) -> -0.61547878 | AB12: F45 | AC12: 0.023870705 | AD12: 0.036768416 | AE12: 0.018530313 | AF12: 0.020789819 | AG12: 0.022862935 | AH12: 0.026198074 | AI12: 0.033300957 | AJ12: F45
A13: G00 | B13: 0.0383362 | C13: 0.0249249 | D13: 0.0028751 | E13: 0.0051592 | F13: 0.0046214 | G13: 0.009557 | H13: 0.0504283 | J13: G00 | K13: =B13/AC13 -> 3.1345558 | L13: =C13/AD13 -> 3.037674 | M13: =D13/AE13 -> 1.5272769 | N13: =E13/AF13 -> 2.0564493 | O13: =F13/AG13 -> 1.2022577 | P13: =G13/AH13 -> 1.8433186 | Q13: =H13/AI13 -> 2.5699361 | S13: G00 | T13: =IF(T35=0,0,((1-B13)*(K35/T35))-1) -> -3.061588 | U13: =IF(U35=0,0,((1-C13)*(L35/U35))-1) -> -4.0703434 | V13: =IF(V35=0,0,((1-D13)*(M35/V35))-1) -> -3.0359568 | W13: =IF(W35=0,0,((1-E13)*(N35/W35))-1) -> -3.6454687 | X13: =IF(X35=0,0,((1-F13)*(O35/X35))-1) -> -3.7637503 | Y13: =IF(Y35=0,0,((1-G13)*(P35/Y35))-1) -> -3.1531767 | Z13: =IF(Z35=0,0,((1-H13)*(Q35/Z35))-1) -> -2.0594184 | AB13: G00 | AC13: 0.012230186 | AD13: 0.0082052583 | AE13: 0.0018825008 | AF13: 0.0025087903 | AG13: 0.0038439347 | AH13: 0.0051846709 | AI13: 0.019622395 | AJ13: G00
... A21: OP0 | B21: 0.0595218 | C21: 0.044146 | D21: 0.0303179 | E21: 0.0290499 | F21: 0.0657309 | G21: 0.0453411 | H21: 0.0642622 | J21: OP0 | K21: =B21/AC21 -> 1.4112976 | L21: =C21/AD21 -> 1.4666599 | M21: =D21/AE21 -> 1.3202003 | N21: =E21/AF21 -> 1.0095392 | O21: =F21/AG21 -> 2.0659569 | P21: =G21/AH21 -> 1.3238973 | Q21: =H21/AI21 -> 1.3529573 | S21: OP0 | T21: =IF(T43=0,0,((1-B21)*(K43/T43))-1) -> -1.3893299 | U21: =IF(U43=0,0,((1-C21)*(L43/U43))-1) -> -1.7355895 | V21: =IF(V43=0,0,((1-D21)*(M43/V43))-1) -> -1.4308825 | W21: =IF(W43=0,0,((1-E21)*(N43/W43))-1) -> -1.1449405 | X21: =IF(X43=0,0,((1-F21)*(O43/X43))-1) -> -1.2367871 | Y21: =IF(Y43=0,0,((1-G21)*(P43/Y43))-1) -> -1.5015167 | Z21: =IF(Z43=0,0,((1-H21)*(Q43/Z43))-1) -> -1.1546702 | AB21: OP0 | AC21: 0.042175229 | AD21: 0.030099684 | AE21: 0.022964621 | AF21: 0.028775405 | AG21: 0.031816201 | AH21: 0.0342482 | AI21: 0.047497583 | AJ21: OP0
A23: alpha-07 | B23: M1 | C23: M2 | D23: Q1 | E23: Q2 | F23: Q3 | G23: Q4 | H23: Q5 | J23: CMIN | K23: M1 | L23: M2 | M23: Q1 | N23: Q2 | O23: Q3 | P23: Q4 | Q23: Q5 | S23: Cmoyen | T23: M1 | U23: M2 | V23: Q1 | W23: Q2 | X23: Q3 | Y23: Q4 | Z23: Q5
A24: A00 | B24: 3519.686 | C24: 982.9798 | D24: -182.8151 | E24: -22.64994 | F24: 1695.083 | G24: 1224.933 | H24: 8082.886 | J24: A00 | K24: 3512.2879 | L24: 585.75059 | M24: -236.25641 | N24: -149.46257 | O24: 1263.2685 | P24: 802.76576 | Q24: 9265.5097 | S24: A00 | T24: =Cmoyen!C3 -> 8903.7381 | U24: =Cmoyen!D3 -> 7273.3084 | V24: =Cmoyen!Q3 -> 3073.4509 | W24: =Cmoyen!R3 -> 5261.3341 | X24: =Cmoyen!S3 -> 7264.2987 | Y24: =Cmoyen!T3 -> 9755.9059 | Z24: =Cmoyen!U3 -> 16333.404
A25: B05 | B25: 203.093 | C25: 46.12926 | D25: -54.12654 | E25: 37.9723 | F25: -10.33008 | G25: 79.31883 | H25: 346.9522 | J25: B05 | K25: 195.69494 | L25: -351.09995 | M25: -107.56785 | N25: -88.840331 | O25: -442.14459 | P25: -342.84841 | Q25: 1529.5759 | S25: B05 | T25: =Cmoyen!C4 -> 999.09308 | U25: =Cmoyen!D4 -> 490.12816 | V25: =Cmoyen!Q4 -> 259.93889 | W25: =Cmoyen!R4 -> 444.3664 | X25: =Cmoyen!S4 -> 623.63664 | Y25: =Cmoyen!T4 -> 907.19373 | Z25: =Cmoyen!U4 -> 1799.0147
A26: C00 | B26: 23.63762 | C26: 21.25776 | D26: 2.010127 | E26: 6.382972 | F26: 13.91652 | G26: 20.37423 | H26: 48.03528 | J26: C00 | K26: 16.239565 | L26: -375.97145 | M26: -51.431184 | N26: -120.42966 | O26: -417.89799 | P26: -401.79301 | Q26: 1230.659 | S26: C00 | T26: =Cmoyen!C5 -> 36.639876 | U26: =Cmoyen!D5 -> 45.558503 | V26: =Cmoyen!Q5 -> 20.26138 | W26: =Cmoyen!R5 -> 32.050804 | X26: =Cmoyen!S5 -> 40.190871 | Y26: =Cmoyen!T5 -> 48.591316 | Z26: =Cmoyen!U5 -> 60.967972
A27: D01 | B27: 8182.226 | C27: 4899.013 | D27: 307.5542 | E27: 757.6595 | F27: 5560.505 | G27: 3880.171 | H27: 17213.97 | J27: D01 | K27: 8174.8279 | L27: 4501.7838 | M27: 254.11289 | N27: 630.84687 | O27: 5128.6905 | P27: 3458.0038 | Q27: 18396.594 | S27: D01 | T27: =Cmoyen!C6 -> 14805.197 | U27: =Cmoyen!D6 -> 14469.376 | V27: =Cmoyen!Q6 -> 6558.1514 | W27: =Cmoyen!R6 -> 10613.166 | X27: =Cmoyen!S6 -> 13693.826 | Y27: =Cmoyen!T6 -> 17718.93 | Z27: =Cmoyen!U6 -> 25344.363
A28: D02 | B28: -338.3088 | C28: -196.709 | D28: -244.0005 | E28: -570.4854 | F28: -378.7966 | G28: -926.5252 | H28: 426.8179 | J28: D02 | K28: -345.70686 | L28: -593.93821 | M28: -297.44181 | N28: -697.29803 | O28: -810.61111 | P28: -1348.6924 | Q28: 1609.4416 | S28: D02 | T28: =Cmoyen!C7 -> 2635.0914 | U28: =Cmoyen!D7 -> 1627.5919 | V28: =Cmoyen!Q7 -> 492.80694 | W28: =Cmoyen!R7 -> 969.35768 | X28: =Cmoyen!S7 -> 1513.7152 | Y28: =Cmoyen!T7 -> 2477.4505 | Z28: =Cmoyen!U7 -> 5890.0111
A29: D03 | B29: 1054.754 | C29: 218.3792 | D29: -116.2874 | E29: 275.9315 | F29: -271.1879 | G29: -162.3641 | H29: 2466.258 | J29: D03 | K29: 1047.3559 | L29: -178.85001 | M29: -169.72871 | N29: 149.11887 | O29: -703.00241 | P29: -584.53134 | Q29: 3648.8817 | S29: D03 | T29: =Cmoyen!C8 -> 2823.4891 | U29: =Cmoyen!D8 -> 1739.5947 | V29: =Cmoyen!Q8 -> 771.24545 | W29: =Cmoyen!R8 -> 1443.3091 | X29: =Cmoyen!S8 -> 2019.1094 | Y29: =Cmoyen!T8 -> 2810.9826 | Z29: =Cmoyen!U8 -> 5055.0703
A30: D04 | B30: -5492.049 | C30: -2391.524 | D30: -156.2211 | E30: -230.7233 | F30: -1028.797 | G30: -909.3222 | H30: -13009.62 | J30: D04 | K30: -5499.4471 | L30: -2788.7532 | M30: -209.66241 | N30: -357.53593 | O30: -1460.6115 | P30: -1331.4894 | Q30: -11826.996 | S30: D04 | T30: =Cmoyen!C9 -> 3992.0106 | U30: =Cmoyen!D9 -> 1921.7387 | V30: =Cmoyen!Q9 -> 463.09525 | W30: =Cmoyen!R9 -> 854.39989 | X30: =Cmoyen!S9 -> 1406.1362 | Y30: =Cmoyen!T9 -> 2228.4645 | Z30: =Cmoyen!U9 -> 11211.413
A31: D05 | B31: -421.8057 | C31: -195.9771 | D31: -42.00931 | E31: -129.7038 | F31: -194.7731 | G31: -368.2737 | H31: -355.1542 | J31: D05 | K31: -429.20376 | L31: -593.20631 | M31: -95.450621 | N31: -256.51643 | O31: -626.58761 | P31: -790.44094 | Q31: 827.46948 | S31: D05 | T31: =Cmoyen!C10 -> 800.99902 | U31: =Cmoyen!D10 -> 468.08512 | V31: =Cmoyen!Q10 -> 118.14339 | W31: =Cmoyen!R10 -> 227.83415 | X31: =Cmoyen!S10 -> 364.71874 | Y31: =Cmoyen!T10 -> 605.12473 | Z31: =Cmoyen!U10 -> 2087.1961
A32: D23 | B32: -2562.946 | C32: -814.149 | D32: 242.6336 | E32: 356.3714 | F32: 697.5578 | G32: 266.8178 | H32: -7113.544 | J32: D23 | K32: -2570.3441 | L32: -1211.3782 | M32: 189.19229 | N32: 229.55877 | O32: 265.74329 | P32: -155.34944 | Q32: -5930.9203 | S32: D23 | T32: =Cmoyen!C11 -> 3327.6159 | U32: =Cmoyen!D11 -> 2180.5471 | V32: =Cmoyen!Q11 -> 964.24832 | W32: =Cmoyen!R11 -> 1427.0875 | X32: =Cmoyen!S11 -> 1840.5744 | Y32: =Cmoyen!T11 -> 2430.7236 | Z32: =Cmoyen!U11 -> 7899.3666
A33: E00 | B33: 1340.92 | C33: 917.1245 | D33: 331.566 | E33: 581.1782 | F33: 999.285 | G33: 911.6127 | H33: 2045.601 | J33: E00 | K33: 1333.5219 | L33: 519.89529 | M33: 278.12469 | N33: 454.36557 | O33: 567.47049 | P33: 489.44546 | Q33: 3228.2247 | S33: E00 | T33: =Cmoyen!C12 -> 2182.9144 | U33: =Cmoyen!D12 -> 1874.2565 | V33: =Cmoyen!Q12 -> 1134.8438 | W33: =Cmoyen!R12 -> 1629.8409 | X33: =Cmoyen!S12 -> 1950.614 | Y33: =Cmoyen!T12 -> 2351.0524 | Z33: =Cmoyen!U12 -> 3300.8768
A34: F45 | B34: -487.5243 | C34: -763.4414 | D34: -233.1098 | E34: -806.5016 | F34: -261.6919 | G34: 526.5921 | H34: 567.0766 | J34: F45 | K34: -494.92236 | L34: -1160.6706 | M34: -286.55111 | N34: -933.31423 | O34: -693.50641 | P34: 104.42486 | Q34: 1749.7003 | S34: F45 | T34: =Cmoyen!C13 -> 1566.3146 | U34: =Cmoyen!D13 -> 1601.961 | V34: =Cmoyen!Q13 -> 347.32592 | W34: =Cmoyen!R13 -> 655.66527 | X34: =Cmoyen!S13 -> 997.67225 | Y34: =Cmoyen!T13 -> 1603.154 | Z34: =Cmoyen!U13 -> 4418.2531
A35: G00 | B35: -1712.986 | C35: -728.4591 | D35: -18.60448 | E35: -83.58695 | F35: -33.92428 | G35: -267.5598 | H35: -4087.219 | J35: G00 | K35: -1720.3841 | L35: -1125.6883 | M35: -72.045791 | N35: -210.39958 | O35: -465.73879 | P35: -689.72704 | Q35: -2904.5953 | S35: G00 | T35: =Cmoyen!C14 -> 802.50325 | U35: =Cmoyen!D14 -> 357.49443 | V35: =Cmoyen!Q14 -> 35.284959 | W35: =Cmoyen!R14 -> 79.121741 | X35: =Cmoyen!S14 -> 167.73817 | Y35: =Cmoyen!T14 -> 317.26859 | Z35: =Cmoyen!U14 -> 2603.4298
... A43: OP0 | B43: -1138.221 | C43: -611.984 | D43: -137.8271 | E43: -8.658228 | F43: 79.938 | G43: -678.8163 | H43: -2224.264 | J43: OP0 | K43: -1145.6191 | L43: -1009.2132 | M43: -191.26841 | N43: -135.47086 | O43: -351.87651 | P43: -1100.9835 | Q43: -1041.6403 | S43: OP0 | T43: =Cmoyen!C22 -> 2767.3952 | U43: =Cmoyen!D22 -> 1311.4114 | V43: =Cmoyen!Q22 -> 430.4411 | W43: =Cmoyen!R22 -> 907.51312 | X43: =Cmoyen!S22 -> 1388.3668 | Y43: =Cmoyen!T22 -> 2095.7701 | Z43: =Cmoyen!U22 -> 6301.8111

Sheet 20pdts2014
A1: beta-14 | B1: M1 | C1: M2 | D1: Q1 | E1: Q2 | F1: Q3 | G1: Q4 | H1: Q5 | J1: Elasticité-revenu 2014 | K1: M1 | L1: M2 | M1: Q1 | N1: Q2 | O1: Q3 | P1: Q4 | Q1: Q5 | S1: Elasticité-Prix 2014 | T1: M1 | U1: M2 | V1: Q1 | W1: Q2 | X1: Q3 | Y1: Q4 | Z1: Q5 | AB1: CB | AC1: M1 | AD1: M2 | AE1: Q1 | AF1: Q2 | AG1: Q3 | AH1: Q4 | AI1: Q5 | AJ1: CB-2014
A2: A00 | B2: 0.0470224 | C2: 0.1347135 | D2: 0.2015948 | E2: 0.1581558 | F2: 0.1443382 | G2: 0.1029208 | H2: 0.0378726 | J2: A00 | K2: =B2/AC2 -> 0.43941571 | L2: =C2/AD2 -> 0.68726763 | M2: =D2/AE2 -> 1.0081283 | N2: =E2/AF2 -> 0.92102559 | O2: =F2/AG2 -> 0.93601863 | P2: =G2/AH2 -> 0.7847426 | Q2: =H2/AI2 -> 0.44912121 | S2: A00 | T2: =IF(T24=0,0,((1-B2)*(K24/T24))-1) -> -0.46925147 | U2: =IF(U24=0,0,((1-C2)*(L24/U24))-1) -> -0.76764886 | V2: =IF(V24=0,0,((1-D2)*(M24/V24))-1) -> -1.0159987 | W2: =IF(W24=0,0,((1-E2)*(N24/W24))-1) -> -0.9571373 | X2: =IF(X24=0,0,((1-F2)*(O24/X24))-1) -> -0.96999894 | Y2: =IF(Y24=0,0,((1-G2)*(P24/Y24))-1) -> -0.83774863 | Z2: =IF(Z24=0,0,((1-H2)*(Q24/Z24))-1) -> -0.43986601 | AB2: A00 | AC2: 0.1070112 | AD2: 0.19601316 | AE2: 0.19996939 | AF2: 0.17171705 | AG2: 0.15420441 | AH2: 0.1311523 | AI2: 0.084326011 | AJ2: A00
A3: B05 | B3: 0.0131922 | C3: 0.0113468 | D3: 0.0136562 | E3: 0.0123499 | F3: 0.0132427 | G3: 0.0152598 | H3: 0.0124194 | J3: B05 | K3: =B3/AC3 -> 0.91298027 | L3: =C3/AD3 -> 0.87564473 | M3: =D3/AE3 -> 1.0302135 | N3: =E3/AF3 -> 0.84754111 | O3: =F3/AG3 -> 0.93151282 | P3: =G3/AH3 -> 1.0645746 | Q3: =H3/AI3 -> 0.89581221 | S3: B05 | T3: =IF(T25=0,0,((1-B3)*(K25/T25))-1) -> -0.94078405 | U3: =IF(U25=0,0,((1-C3)*(L25/U25))-1) -> -1.5381681 | V3: =IF(V25=0,0,((1-D3)*(M25/V25))-1) -> -1.2070165 | W3: =IF(W25=0,0,((1-E3)*(N25/W25))-1) -> -1.1760003 | X3: =IF(X25=0,0,((1-F3)*(O25/X25))-1) -> -1.2419467 | Y3: =IF(Y25=0,0,((1-G3)*(P25/Y25))-1) -> -1.3734577 | Z3: =IF(Z25=0,0,((1-H3)*(Q25/Z25))-1) -> -0.70906684 | AB3: B05 | AC3: 0.0144496 | AD3: 0.012958223 | AE3: 0.013255699 | AF3: 0.014571446 | AG3: 0.014216337 | AH3: 0.014334176 | AI3: 0.013863843 | AJ3: B05
A4: C00 | B4: 5.87e-05 | C4: 0.0005982 | D4: 0.0008966 | E4: 0.0007401 | F4: 0.0004352 | G4: 0.000316 | H4: 5.33e-05 | J4: C00 | K4: =B4/AC4 -> 0.14988081 | L4: =C4/AD4 -> 0.49977364 | M4: =D4/AE4 -> 0.70487045 | N4: =E4/AF4 -> 0.80695521 | O4: =F4/AG4 -> 0.6035612 | P4: =G4/AH4 -> 0.55729799 | Q4: =H4/AI4 -> 0.19943148 | S4: C00 | T4: =IF(T26=0,0,((1-B4)*(K26/T26))-1) -> -1.1464155 | U4: =IF(U26=0,0,((1-C4)*(L26/U26))-1) -> -7.7351474 | V4: =IF(V26=0,0,((1-D4)*(M26/V26))-1) -> -2.5757508 | W4: =IF(W26=0,0,((1-E4)*(N26/W26))-1) -> -6.056691 | X4: =IF(X26=0,0,((1-F4)*(O26/X26))-1) -> -6.7855923 | Y4: =IF(Y26=0,0,((1-G4)*(P26/Y26))-1) -> -8.5095617 | Z4: =IF(Z26=0,0,((1-H4)*(Q26/Z26))-1) -> 9.6770588 | AB4: C00 | AC4: 0.00039164453 | AD4: 0.0011969419 | AE4: 0.0012720068 | AF4: 0.00091715127 | AG4: 0.00072105364 | AH4: 0.0005670216 | AI4: 0.00026725971 | AJ4: C00
A5: D01 | B5: 0.1029789 | C5: 0.1940067 | D5: 0.2834289 | E5: 0.2450719 | F5: 0.2244558 | G5: 0.1793792 | H5: 0.0839503 | J5: D01 | K5: =B5/AC5 -> 0.49934654 | L5: =C5/AD5 -> 0.67609162 | M5: =D5/AE5 -> 0.94815138 | N5: =E5/AF5 -> 0.87102785 | O5: =F5/AG5 -> 0.8483727 | P5: =G5/AH5 -> 0.75780866 | Q5: =H5/AI5 -> 0.50813638 | S5: D01 | T5: =IF(T27=0,0,((1-B5)*(K27/T27))-1) -> -0.55260077 | U5: =IF(U27=0,0,((1-C5)*(L27/U27))-1) -> -0.76327063 | V5: =IF(V27=0,0,((1-D5)*(M27/V27))-1) -> -0.96855613 | W5: =IF(W27=0,0,((1-E5)*(N27/W27))-1) -> -0.91556335 | X5: =IF(X27=0,0,((1-F5)*(O27/X27))-1) -> -0.89547843 | Y5: =IF(Y27=0,0,((1-G5)*(P27/Y27))-1) -> -0.81688994 | Z5: =IF(Z27=0,0,((1-H5)*(Q27/Z27))-1) -> -0.53479219 | AB5: D01 | AC5: 0.20622732 | AD5: 0.28695327 | AE5: 0.2989279 | AF5: 0.28135943 | AG5: 0.26457216 | AH5: 0.23670777 | AI5: 0.16521214 | AJ5: D01
A6: D02 | B6: 0.0523622 | C6: 0.0476485 | D6: 0.0494428 | E6: 0.0499941 | F6: 0.0460122 | G6: 0.0492105 | H6: 0.0574054 | J6: D02 | K6: =B6/AC6 -> 1.3992968 | L6: =C6/AD6 -> 1.2880911 | M6: =D6/AE6 -> 1.6131836 | N6: =E6/AF6 -> 1.5097089 | O6: =F6/AG6 -> 1.2173575 | P6: =G6/AH6 -> 1.2576494 | Q6: =H6/AI6 -> 1.4575589 | S6: D02 | T6: =IF(T28=0,0,((1-B6)*(K28/T28))-1) -> -1.3882729 | U6: =IF(U28=0,0,((1-C6)*(L28/U28))-1) -> -1.4974515 | V6: =IF(V28=0,0,((1-D6)*(M28/V28))-1) -> -1.6567292 | W6: =IF(W28=0,0,((1-E6)*(N28/W28))-1) -> -1.6224516 | X6: =IF(X28=0,0,((1-F6)*(O28/X28))-1) -> -1.3199136 | Y6: =IF(Y28=0,0,((1-G6)*(P28/Y28))-1) -> -1.3545694 | Z6: =IF(Z28=0,0,((1-H6)*(Q28/Z28))-1) -> -1.3681163 | AB6: D02 | AC6: 0.037420366 | AD6: 0.036991562 | AE6: 0.030649209 | AF6: 0.033115059 | AG6: 0.037796784 | AH6: 0.03912895 | AI6: 0.039384618 | AJ6: D02
A7: D03 | B7: 0.0435263 | C7: 0.0539264 | D7: 0.0579767 | E7: 0.055323 | F7: 0.0536292 | G7: 0.0575638 | H7: 0.0398668 | J7: D03 | K7: =B7/AC7 -> 0.8938189 | L7: =C7/AD7 -> 1.0997427 | M7: =D7/AE7 -> 1.2205015 | N7: =E7/AF7 -> 1.1264975 | O7: =F7/AG7 -> 1.0895546 | P7: =G7/AH7 -> 1.1435966 | Q7: =H7/AI7 -> 0.83214508 | S7: D03 | T7: =IF(T29=0,0,((1-B7)*(K29/T29))-1) -> -0.90610565 | U7: =IF(U29=0,0,((1-C7)*(L29/U29))-1) -> -1.2615479 | V7: =IF(V29=0,0,((1-D7)*(M29/V29))-1) -> -1.2549474 | W7: =IF(W29=0,0,((1-E7)*(N29/W29))-1) -> -1.21218 | X7: =IF(X29=0,0,((1-F7)*(O29/X29))-1) -> -1.1704938 | Y7: =IF(Y29=0,0,((1-G7)*(P29/Y29))-1) -> -1.2197807 | Z7: =IF(Z29=0,0,((1-H7)*(Q29/Z29))-1) -> -0.78593367 | AB7: D03 | AC7: 0.048697001 | AD7: 0.049035472 | AE7: 0.047502358 | AF7: 0.049110626 | AG7: 0.049221215 | AH7: 0.050335754 | AI7: 0.047908473 | AJ7: D03
A8: D04 | B8: 0.0940943 | C8: 0.0607339 | D8: 0.020388 | E8: 0.0380171 | F8: 0.0332085 | G8: 0.0548393 | H8: 0.1115951 | J8: D04 | K8: =B8/AC8 -> 2.3605374 | L8: =C8/AD8 -> 2.3144919 | M8: =D8/AE8 -> 1.1481887 | N8: =E8/AF8 -> 1.8717413 | O8: =F8/AG8 -> 1.4716277 | P8: =G8/AH8 -> 1.7825806 | Q8: =H8/AI8 -> 1.9652021 | S8: D04 | T8: =IF(T30=0,0,((1-B8)*(K30/T30))-1) -> -2.2413891 | U8: =IF(U30=0,0,((1-C8)*(L30/U30))-1) -> -2.5448232 | V8: =IF(V30=0,0,((1-D8)*(M30/V30))-1) -> -1.2765565 | W8: =IF(W30=0,0,((1-E8)*(N30/W30))-1) -> -2.0668026 | X8: =IF(X30=0,0,((1-F8)*(O30/X30))-1) -> -1.6470233 | Y8: =IF(Y30=0,0,((1-G8)*(P30/Y30))-1) -> -1.878242 | Z8: =IF(Z30=0,0,((1-H8)*(Q30/Z30))-1) -> -1.8161916 | AB8: D04 | AC8: 0.039861389 | AD8: 0.026240706 | AE8: 0.017756663 | AF8: 0.020311087 | AG8: 0.02256583 | AH8: 0.030763995 | AI8: 0.056785559 | AJ8: D04
A9: D05 | B9: 0.0167256 | C9: 0.0161845 | D9: 0.0082578 | E9: 0.0072641 | F9: 0.0088088 | G9: 0.0155573 | H9: 0.0166634 | J9: D05 | K9: =B9/AC9 -> 1.6027839 | L9: =C9/AD9 -> 1.9366787 | M9: =D9/AE9 -> 1.8144895 | N9: =E9/AF9 -> 1.2806437 | O9: =F9/AG9 -> 1.2370681 | P9: =G9/AH9 -> 1.5930688 | Q9: =H9/AI9 -> 1.1697722 | S9: D05 | T9: =IF(T31=0,0,((1-B9)*(K31/T31))-1) -> -1.6294804 | U9: =IF(U31=0,0,((1-C9)*(L31/U31))-1) -> -2.9416329 | V9: =IF(V31=0,0,((1-D9)*(M31/V31))-1) -> -2.3267504 | W9: =IF(W31=0,0,((1-E9)*(N31/W31))-1) -> -2.1218688 | X9: =IF(X31=0,0,((1-F9)*(O31/X31))-1) -> -1.8557282 | Y9: =IF(Y31=0,0,((1-G9)*(P31/Y31))-1) -> -2.0385284 | Z9: =IF(Z31=0,0,((1-H9)*(Q31/Z31))-1) -> -0.98471783 | AB9: D05 | AC9: 0.010435343 | AD9: 0.0083568328 | AE9: 0.004551032 | AF9: 0.0056722256 | AG9: 0.0071207074 | AH9: 0.0097656173 | AI9: 0.014244996 | AJ9: D05
A10: D23 | B10: 0.0396437 | C10: 0.0470316 | D10: 0.0292885 | E10: 0.0364507 | F10: 0.0392104 | G10: 0.0476646 | H10: 0.0389674 | J10: D23 | K10: =B10/AC10 -> 1.1492443 | L10: =C10/AD10 -> 1.2253802 | M10: =D10/AE10 -> 0.7958992 | N10: =E10/AF10 -> 1.1013455 | O10: =F10/AG10 -> 1.2372241 | P10: =G10/AH10 -> 1.3914532 | Q10: =H10/AI10 -> 1.01196 | S10: D23 | T10: =IF(T32=0,0,((1-B10)*(K32/T32))-1) -> -1.1541921 | U10: =IF(U32=0,0,((1-C10)*(L32/U32))-1) -> -1.4299289 | V10: =IF(V32=0,0,((1-D10)*(M32/V32))-1) -> -0.86469977 | W10: =IF(W32=0,0,((1-E10)*(N32/W32))-1) -> -1.2379255 | X10: =IF(X32=0,0,((1-F10)*(O32/X32))-1) -> -1.3631172 | Y10: =IF(Y32=0,0,((1-G10)*(P32/Y32))-1) -> -1.4981911 | Z10: =IF(Z32=0,0,((1-H10)*(Q32/Z32))-1) -> -0.9456121 | AB10: D23 | AC10: 0.03449545 | AD10: 0.03838123 | AE10: 0.036799258 | AF10: 0.033096517 | AG10: 0.031692237 | AH10: 0.034255267 | AI10: 0.038506857 | AJ10: D23
A11: E00 | B11: 0.0136935 | C11: 0.0139224 | D11: 0.0296782 | E11: 0.0272576 | F11: 0.028407 | G11: 0.0203938 | H11: 0.0120507 | J11: E00 | K11: =B11/AC11 -> 0.33935849 | L11: =C11/AD11 -> 0.40911001 | M11: =D11/AE11 -> 0.56419093 | N11: =E11/AF11 -> 0.55677895 | O11: =F11/AG11 -> 0.62716771 | P11: =G11/AH11 -> 0.51664714 | Q11: =H11/AI11 -> 0.43526639 | S11: E00 | T11: =IF(T33=0,0,((1-B11)*(K33/T33))-1) -> -0.35794383 | U11: =IF(U33=0,0,((1-C11)*(L33/U33))-1) -> -0.66841785 | V11: =IF(V33=0,0,((1-D11)*(M33/V33))-1) -> -0.62105727 | W11: =IF(W33=0,0,((1-E11)*(N33/W33))-1) -> -0.66459743 | X11: =IF(X33=0,0,((1-F11)*(O33/X33))-1) -> -0.73341825 | Y11: =IF(Y33=0,0,((1-G11)*(P33/Y33))-1) -> -0.63844029 | Z11: =IF(Z33=0,0,((1-H11)*(Q33/Z33))-1) -> -0.34787286 | AB11: E00 | AC11: 0.040351134 | AD11: 0.034030944 | AE11: 0.052603115 | AF11: 0.048955874 | AG11: 0.045294105 | AH11: 0.039473363 | AI11: 0.027685804 | AJ11: E00
A12: F45 | B12: 0.0258411 | C12: 0.0640816 | D12: 0.0210816 | E12: 0.030812 | F12: 0.0388789 | G12: 0.0390992 | H12: 0.0239583 | J12: F45 | K12: =B12/AC12 -> 1.2938645 | L12: =C12/AD12 -> 2.177485 | M12: =D12/AE12 -> 1.929453 | N12: =E12/AF12 -> 1.9540441 | O12: =F12/AG12 -> 1.9035969 | P12: =G12/AH12 -> 1.5996144 | Q12: =H12/AI12 -> 0.86265025 | S12: F45 | T12: =IF(T34=0,0,((1-B12)*(K34/T34))-1) -> -1.3053063 | U12: =IF(U34=0,0,((1-C12)*(L34/U34))-1) -> -2.377605 | V12: =IF(V34=0,0,((1-D12)*(M34/V34))-1) -> -2.1232328 | W12: =IF(W34=0,0,((1-E12)*(N34/W34))-1) -> -2.2207943 | X12: =IF(X34=0,0,((1-F12)*(O34/X34))-1) -> -2.0783226 | Y12: =IF(Y34=0,0,((1-G12)*(P34/Y34))-1) -> -1.7534853 | Z12: =IF(Z34=0,0,((1-H12)*(Q34/Z34))-1) -> -0.7731724 | AB12: F45 | AC12: 0.019972029 | AD12: 0.029429181 | AE12: 0.010926206 | AF12: 0.015768324 | AG12: 0.020423914 | AH12: 0.02444289 | AI12: 0.027772901 | AJ12: F45
A13: G00 | B13: 0.0223932 | C13: 0.0293234 | D13: 0.0105011 | E13: 0.0124613 | F13: 0.0201053 | G13: 0.0325594 | H13: 0.0207139 | J13: G00 | K13: =B13/AC13 -> 1.7969774 | L13: =C13/AD13 -> 2.5575422 | M13: =D13/AE13 -> 2.6253203 | N13: =E13/AF13 -> 2.525217 | O13: =F13/AG13 -> 2.729942 | P13: =G13/AH13 -> 2.4549828 | Q13: =H13/AI13 -> 1.1079869 | S13: G00 | T13: =IF(T35=0,0,((1-B13)*(K35/T35))-1) -> -1.8097463 | U13: =IF(U35=0,0,((1-C13)*(L35/U35))-1) -> -3.2454699 | V13: =IF(V35=0,0,((1-D13)*(M35/V35))-1) -> -3.1974184 | W13: =IF(W35=0,0,((1-E13)*(N35/W35))-1) -> -3.4704182 | X13: =IF(X35=0,0,((1-F13)*(O35/X35))-1) -> -3.2885067 | Y13: =IF(Y35=0,0,((1-G13)*(P35/Y35))-1) -> -2.7366304 | Z13: =IF(Z35=0,0,((1-H13)*(Q35/Z35))-1) -> -0.96747661 | AB13: G00 | AC13: 0.012461593 | AD13: 0.011465461 | AE13: 0.003999931 | AF13: 0.0049347442 | AG13: 0.0073647352 | AH13: 0.013262578 | AI13: 0.018695076 | AJ13: G00
... A21: OP0 | B21: 0.0872994 | C21: 0.0490094 | D21: 0.0342167 | E21: 0.0389905 | F21: 0.038869 | G21: 0.0416842 | H21: 0.0998879 | J21: OP0 | K21: =B21/AC21 -> 1.8280613 | L21: =C21/AD21 -> 1.6947389 | M21: =D21/AE21 -> 1.3759452 | N21: =E21/AF21 -> 1.2817967 | O21: =F21/AG21 -> 1.1785491 | P21: =G21/AH21 -> 1.1449787 | Q21: =H21/AI21 -> 1.6479335 | S21: OP0 | T21: =IF(T43=0,0,((1-B21)*(K43/T43))-1) -> -1.7632311 | U21: =IF(U43=0,0,((1-C21)*(L43/U43))-1) -> -1.945646 | V21: =IF(V43=0,0,((1-D21)*(M43/V43))-1) -> -1.4555749 | W21: =IF(W43=0,0,((1-E21)*(N43/W43))-1) -> -1.423029 | X21: =IF(X43=0,0,((1-F21)*(O43/X43))-1) -> -1.3015678 | Y21: =IF(Y43=0,0,((1-G21)*(P43/Y43))-1) -> -1.2576663 | Z21: =IF(Z43=0,0,((1-H21)*(Q43/Z43))-1) -> -1.544013 | AB21: OP0 | AC21: 0.047755182 | AD21: 0.028918554 | AE21: 0.024867778 | AF21: 0.03041863 | AG21: 0.032980383 | AH21: 0.036406091 | AI21: 0.060614035 | AJ21: OP0
A23: alpha-14 | B23: M1 | C23: M2 | D23: Q1 | E23: Q2 | F23: Q3 | G23: Q4 | H23: Q5 | J23: CMIN | K23: M1 | L23: M2 | M23: Q1 | N23: Q2 | O23: Q3 | P23: Q4 | Q23: Q5 | S23: Cmoyen | T23: M1 | U23: M2 | V23: Q1 | W23: Q2 | X23: Q3 | Y23: Q4 | Z23: Q5
A24: A00 | B24: 5124.199 | C24: 3423.398 | D24: -60.96007 | E24: 696.0611 | F24: 628.7005 | G24: 2336.466 | H24: 6589.361 | J24: A00 | K24: 5090.8615 | L24: 2939.4734 | M24: -150.27922 | N24: 448.75598 | O24: 344.53113 | P24: 1963.1735 | Q24: 6963.8056 | S24: A00 | T24: =Cmoyen!F3 -> 9140.8204 | U24: =Cmoyen!G3 -> 10946.736 | V24: =Cmoyen!X3 -> 7499.5859 | W24: =Cmoyen!Y3 -> 8813.7856 | X24: =Cmoyen!Z3 -> 9826.3904 | Y24: =Cmoyen!AA3 -> 10854.282 | Z24: =Cmoyen!AB3 -> 11961.545
A25: B05 | B25: 107.4033 | C25: 89.99472 | D25: -15.02138 | E25: 114.026 | F25: 62.04597 | G25: -76.60921 | H25: 204.8908 | J25: B05 | K25: 74.06584 | L25: -393.92985 | M25: -104.34053 | N25: -133.27912 | O25: -222.1234 | P25: -449.90173 | Q25: 579.33538 | S25: B05 | T25: =Cmoyen!F4 -> 1234.2746 | U25: =Cmoyen!G4 -> 723.67721 | V25: =Cmoyen!X4 -> 497.13735 | W25: =Cmoyen!Y4 -> 747.9141 | X25: =Cmoyen!Z4 -> 905.90974 | Y25: =Cmoyen!AA4 -> 1186.3092 | Z25: =Cmoyen!AB4 -> 1966.5698
A26: C00 | B26: 28.43899 | C26: 33.44046 | D26: 14.08062 | E26: 9.085246 | F26: 18.21835 | G26: 20.7783 | H26: 30.34938 | J26: C00 | K26: -4.8984704 | L26: -450.48411 | M26: -75.238531 | N26: -238.21987 | O26: -265.95102 | P26: -352.51422 | Q26: 404.79396 | S26: C00 | T26: =Cmoyen!F5 -> 33.453998 | U26: =Cmoyen!G5 -> 66.845549 | V26: =Cmoyen!X5 -> 47.704923 | W26: =Cmoyen!Y5 -> 47.074967 | X26: =Cmoyen!Z5 -> 45.947808 | Y26: =Cmoyen!AA5 -> 46.927215 | Z26: =Cmoyen!AB5 -> 37.910476
A27: D01 | B27: 8819.409 | C27: 5190.785 | D27: 581.2645 | E27: 1862.541 | F27: 2556.339 | G27: 4744.56 | H27: 11526.89 | J27: D01 | K27: 8786.0715 | L27: 4706.8604 | M27: 491.94535 | N27: 1615.2359 | O27: 2272.1696 | P27: 4371.2675 | Q27: 11901.335 | S27: D01 | T27: =Cmoyen!F6 -> 17615.792 | U27: =Cmoyen!G6 -> 16025.464 | V27: =Cmoyen!X6 -> 11210.893 | W27: =Cmoyen!Y6 -> 14441.441 | X27: =Cmoyen!Z6 -> 16859.371 | Y27: =Cmoyen!AA6 -> 19590.147 | Z27: =Cmoyen!AB6 -> 23435.148
A28: D02 | B28: -1276.323 | C28: -595.1602 | D28: -704.8282 | E28: -866.3581 | F28: -523.5154 | G28: -834.3551 | H28: -2556.232 | J28: D02 | K28: -1309.6605 | L28: -1079.0848 | M28: -794.14735 | N28: -1113.6632 | O28: -807.68477 | P28: -1207.6476 | Q28: -2181.7874 | S28: D02 | T28: =Cmoyen!F7 -> 3196.4211 | U28: =Cmoyen!G7 -> 2065.8658 | V28: =Cmoyen!X7 -> 1149.4578 | W28: =Cmoyen!Y7 -> 1699.7091 | X28: =Cmoyen!Z7 -> 2408.5301 | Y28: =Cmoyen!AA7 -> 3238.3469 | Z28: =Cmoyen!AB7 -> 5586.6618
A29: D03 | B29: 441.68 | C29: -273.1456 | D29: -392.8261 | E29: -318.8634 | F29: -280.8934 | G29: -598.1996 | H29: 1140.703 | J29: D03 | K29: 408.34254 | L29: -757.07017 | M29: -482.14525 | N29: -566.16852 | O29: -565.06277 | P29: -971.49212 | Q29: 1515.1476 | S29: D03 | T29: =Cmoyen!F8 -> 4159.6633 | U29: =Cmoyen!G8 -> 2738.4814 | V29: =Cmoyen!X8 -> 1781.5128 | W29: =Cmoyen!Y8 -> 2520.7195 | X29: =Cmoyen!Z8 -> 3136.5308 | Y29: =Cmoyen!AA8 -> 4165.8321 | Z29: =Cmoyen!AB8 -> 6795.7605
A30: D04 | B30: -4632.54 | C30: -1926.342 | D30: -98.68393 | E30: -908.8043 | F30: -678.1864 | G30: -1992.499 | H30: -7774.668 | J30: D04 | K30: -4665.8775 | L30: -2410.2666 | M30: -188.00308 | N30: -1156.1094 | O30: -962.35577 | P30: -2365.7915 | Q30: -7400.2234 | S30: D04 | T30: =Cmoyen!F9 -> 3404.9316 | U30: =Cmoyen!G9 -> 1465.4633 | V30: =Cmoyen!X9 -> 665.94005 | W30: =Cmoyen!Y9 -> 1042.5148 | X30: =Cmoyen!Z9 -> 1437.9657 | Y30: =Cmoyen!AA9 -> 2546.0558 | Z30: =Cmoyen!AB9 -> 8054.9648
A31: D05 | B31: -537.313 | C31: -437.1496 | D31: -139.0167 | E31: -81.70624 | F31: -107.5714 | G31: -479.3222 | H31: -343.0416 | J31: D05 | K31: -570.65046 | L31: -921.07417 | M31: -228.33585 | N31: -329.01136 | O31: -391.74077 | P31: -852.61472 | Q31: 31.402978 | S31: D05 | T31: =Cmoyen!F10 -> 891.37963 | U31: =Cmoyen!G10 -> 466.7036 | V31: =Cmoyen!X10 -> 170.6804 | W31: =Cmoyen!Y10 -> 291.14045 | X31: =Cmoyen!Z10 -> 453.75389 | Y31: =Cmoyen!AA10 -> 808.21123 | Z31: =Cmoyen!AB10 -> 2020.6359
A32: D23 | B32: -439.7566 | C32: -483.0976 | D32: 281.682 | E32: -172.1624 | F32: -479.0838 | G32: -1109.767 | H32: -65.32395 | J32: D23 | K32: -473.09406 | L32: -967.02217 | M32: 192.36285 | N32: -419.46752 | O32: -763.25317 | P32: -1483.0595 | Q32: 309.12063 | S32: D23 | T32: =Cmoyen!F11 -> 2946.5769 | U32: =Cmoyen!G11 -> 2143.4745 | V32: =Cmoyen!X11 -> 1380.1072 | W32: =Cmoyen!Y11 -> 1698.7574 | X32: =Cmoyen!Z11 -> 2019.5291 | Y32: =Cmoyen!AA11 -> 2834.9966 | Z32: =Cmoyen!AB11 -> 5462.1524
A33: E00 | B33: 2277.079 | C33: 1123.002 | D33: 859.7666 | E33: 1113.713 | F33: 1076.096 | G33: 1579.044 | H33: 2217.827 | J33: E00 | K33: 2243.7415 | L33: 639.07743 | M33: 770.44745 | N33: 866.40788 | O33: 791.92663 | P33: 1205.7515 | Q33: 2592.2716 | S33: E00 | T33: =Cmoyen!F12 -> 3446.7652 | U33: =Cmoyen!G12 -> 1900.5243 | V33: =Cmoyen!X12 -> 1972.8099 | W33: =Cmoyen!Y12 -> 2512.7765 | X33: =Cmoyen!Z12 -> 2886.283 | Y33: =Cmoyen!AA12 -> 3266.8508 | Z33: =Cmoyen!AB12 -> 3927.1987
A34: F45 | B34: -501.3305 | C34: -1935.234 | D34: -380.8633 | E34: -772.1522 | F34: -1176.012 | G34: -1212.966 | H34: 541.0895 | J34: F45 | K34: -534.66796 | L34: -2419.1586 | M34: -470.18245 | N34: -1019.4573 | O34: -1460.1814 | P34: -1586.2585 | Q34: 915.53408 | S34: F45 | T34: =Cmoyen!F13 -> 1705.9965 | U34: =Cmoyen!G13 -> 1643.5299 | V34: =Cmoyen!X13 -> 409.77281 | W34: =Cmoyen!Y13 -> 809.34667 | X34: =Cmoyen!Z13 -> 1301.4761 | Y34: =Cmoyen!AA13 -> 2022.9155 | Z34: =Cmoyen!AB13 -> 3939.5533
A35: G00 | B35: -848.3492 | C35: -997.3093 | D35: -243.8185 | E35: -386.3166 | F35: -811.8725 | G35: -1597.025 | H35: -286.3723 | J35: G00 | K35: -881.68666 | L35: -1481.2339 | M35: -333.13765 | N35: -633.62172 | O35: -1096.0419 | P35: -1970.3175 | Q35: 88.072278 | S35: G00 | T35: =Cmoyen!F14 -> 1064.4604 | U35: =Cmoyen!G14 -> 640.31098 | V35: =Cmoyen!X14 -> 150.01209 | W35: =Cmoyen!Y14 -> 253.28746 | X35: =Cmoyen!Z14 -> 469.30411 | Y35: =Cmoyen!AA14 -> 1097.6228 | Z35: =Cmoyen!AB14 -> 2651.8746
... A43: OP0 | B43: -3377.839 | C43: -1122.012 | D43: -350.6182 | E43: -439.9709 | F43: -375.2402 | G43: -436.8253 | H43: -5570.953 | J43: OP0 | K43: -3411.1765 | L43: -1605.9366 | M43: -439.93735 | N43: -687.27602 | O43: -659.40957 | P43: -810.11782 | Q43: -5196.5084 | S43: OP0 | T43: =Cmoyen!F22 -> 4079.2138 | U43: =Cmoyen!G22 -> 1615.013 | V43: =Cmoyen!X22 -> 932.63295 | W43: =Cmoyen!Y22 -> 1561.3084 | X43: =Cmoyen!Z22 -> 2101.6139 | Y43: =Cmoyen!AA22 -> 3013.0007 | Z43: =Cmoyen!AB22 -> 8598.0296
J45: VAR Elasticité-revenu 2014/2007 | K45: M1 | L45: M2 | M45: Q1 | N45: Q2 | O45: Q3 | P45: Q4 | Q45: Q5
J46: A00 | K46: =IF('20pdts2007'!K2=0,0,'20pdts2014'!K2/'20pdts2007'!K2-1) -> -0.27332756 | L46: =IF('20pdts2007'!L2=0,0,'20pdts2014'!L2/'20pdts2007'!L2-1) -> -0.20533393 | M46: =IF('20pdts2007'!M2=0,0,'20pdts2014'!M2/'20pdts2007'!M2-1) -> -0.048470354 | N46: =IF('20pdts2007'!N2=0,0,'20pdts2014'!N2/'20pdts2007'!N2-1) -> -0.082922194 | O46: =IF('20pdts2007'!O2=0,0,'20pdts2014'!O2/'20pdts2007'!O2-1) -> 0.22091138 | P46: =IF('20pdts2007'!P2=0,0,'20pdts2014'!P2/'20pdts2007'!P2-1) -> -0.10257892 | Q46: =IF('20pdts2007'!Q2=0,0,'20pdts2014'!Q2/'20pdts2007'!Q2-1) -> -0.1108821
J47: B05 | K47: =IF('20pdts2007'!K3=0,0,'20pdts2014'!K3/'20pdts2007'!K3-1) -> 0.14591767 | L47: =IF('20pdts2007'!L3=0,0,'20pdts2014'!L3/'20pdts2007'!L3-1) -> -0.033378261 | M47: =IF('20pdts2007'!M3=0,0,'20pdts2014'!M3/'20pdts2007'!M3-1) -> -0.14733413 | N47: =IF('20pdts2007'!N3=0,0,'20pdts2014'!N3/'20pdts2007'!N3-1) -> -0.073264593 | O47: =IF('20pdts2007'!O3=0,0,'20pdts2014'!O3/'20pdts2007'!O3-1) -> -0.083668225 | P47: =IF('20pdts2007'!P3=0,0,'20pdts2014'!P3/'20pdts2007'!P3-1) -> 0.1665705 | Q47: =IF('20pdts2007'!Q3=0,0,'20pdts2014'!Q3/'20pdts2007'!Q3-1) -> 0.109854
J48: C00 | K48: =IF('20pdts2007'!K4=0,0,'20pdts2014'!K4/'20pdts2007'!K4-1) -> -0.57773738 | L48: =IF('20pdts2007'!L4=0,0,'20pdts2014'!L4/'20pdts2007'!L4-1) -> -0.063112894 | M48: =IF('20pdts2007'!M4=0,0,'20pdts2014'!M4/'20pdts2007'!M4-1) -> -0.21747412 | N48: =IF('20pdts2007'!N4=0,0,'20pdts2014'!N4/'20pdts2007'!N4-1) -> 0.0075946106 | O48: =IF('20pdts2007'!O4=0,0,'20pdts2014'!O4/'20pdts2007'!O4-1) -> -0.076739623 | P48: =IF('20pdts2007'!P4=0,0,'20pdts2014'!P4/'20pdts2007'!P4-1) -> -0.040278706 | Q48: =IF('20pdts2007'!Q4=0,0,'20pdts2014'!Q4/'20pdts2007'!Q4-1) -> -0.060066849
J49: D01 | K49: =IF('20pdts2007'!K5=0,0,'20pdts2014'!K5/'20pdts2007'!K5-1) -> 0.11625467 | L49: =IF('20pdts2007'!L5=0,0,'20pdts2014'!L5/'20pdts2007'!L5-1) -> 0.022179001 | M49: =IF('20pdts2007'!M5=0,0,'20pdts2014'!M5/'20pdts2007'!M5-1) -> -0.0051957965 | N49: =IF('20pdts2007'!N5=0,0,'20pdts2014'!N5/'20pdts2007'!N5-1) -> -0.062010468 | O49: =IF('20pdts2007'!O5=0,0,'20pdts2014'!O5/'20pdts2007'!O5-1) -> 0.42837974 | P49: =IF('20pdts2007'!P5=0,0,'20pdts2014'!P5/'20pdts2007'!P5-1) -> -0.029713586 | Q49: =IF('20pdts2007'!Q5=0,0,'20pdts2014'!Q5/'20pdts2007'!Q5-1) -> 0.58398023
J50: D02 | K50: =IF('20pdts2007'!K6=0,0,'20pdts2014'!K6/'20pdts2007'!K6-1) -> 0.24008579 | L50: =IF('20pdts2007'!L6=0,0,'20pdts2014'!L6/'20pdts2007'!L6-1) -> 0.14919972 | M50: =IF('20pdts2007'!M6=0,0,'20pdts2014'!M6/'20pdts2007'!M6-1) -> 0.078962684 | N50: =IF('20pdts2007'!N6=0,0,'20pdts2014'!N6/'20pdts2007'!N6-1) -> -0.04961214 | O50: =IF('20pdts2007'!O6=0,0,'20pdts2014'!O6/'20pdts2007'!O6-1) -> -0.026302603 | P50: =IF('20pdts2007'!P6=0,0,'20pdts2014'!P6/'20pdts2007'!P6-1) -> -0.084669928 | Q50: =IF('20pdts2007'!Q6=0,0,'20pdts2014'!Q6/'20pdts2007'!Q6-1) -> 0.57143259
J51: D03 | K51: =IF('20pdts2007'!K7=0,0,'20pdts2014'!K7/'20pdts2007'!K7-1) -> 0.42683219 | L51: =IF('20pdts2007'!L7=0,0,'20pdts2014'!L7/'20pdts2007'!L7-1) -> 0.25761823 | M51: =IF('20pdts2007'!M7=0,0,'20pdts2014'!M7/'20pdts2007'!M7-1) -> 0.060587284 | N51: =IF('20pdts2007'!N7=0,0,'20pdts2014'!N7/'20pdts2007'!N7-1) -> 0.39276561 | O51: =IF('20pdts2007'!O7=0,0,'20pdts2014'!O7/'20pdts2007'!O7-1) -> -0.039456809 | P51: =IF('20pdts2007'!P7=0,0,'20pdts2014'!P7/'20pdts2007'!P7-1) -> 0.081148634 | Q51: =IF('20pdts2007'!Q7=0,0,'20pdts2014'!Q7/'20pdts2007'!Q7-1) -> 0.62489812
J52: D04 | K52: =IF('20pdts2007'!K8=0,0,'20pdts2014'!K8/'20pdts2007'!K8-1) -> -0.0064075238 | L52: =IF('20pdts2007'!L8=0,0,'20pdts2014'!L8/'20pdts2007'!L8-1) -> 0.031202403 | M52: =IF('20pdts2007'!M8=0,0,'20pdts2014'!M8/'20pdts2007'!M8-1) -> -0.14143991 | N52: =IF('20pdts2007'!N8=0,0,'20pdts2014'!N8/'20pdts2007'!N8-1) -> 0.4737624 | O52: =IF('20pdts2007'!O8=0,0,'20pdts2014'!O8/'20pdts2007'!O8-1) -> -0.15015767 | P52: =IF('20pdts2007'!P8=0,0,'20pdts2014'!P8/'20pdts2007'!P8-1) -> 0.26599353 | Q52: =IF('20pdts2007'!Q8=0,0,'20pdts2014'!Q8/'20pdts2007'!Q8-1) -> -0.090349159
J53: D05 | K53: =IF('20pdts2007'!K9=0,0,'20pdts2014'!K9/'20pdts2007'!K9-1) -> 0.04990456 | L53: =IF('20pdts2007'!L9=0,0,'20pdts2014'!L9/'20pdts2007'!L9-1) -> 0.36513256 | M53: =IF('20pdts2007'!M9=0,0,'20pdts2014'!M9/'20pdts2007'!M9-1) -> 0.33852931 | N53: =IF('20pdts2007'!N9=0,0,'20pdts2014'!N9/'20pdts2007'!N9-1) -> -0.18393421 | O53: =IF('20pdts2007'!O9=0,0,'20pdts2014'!O9/'20pdts2007'!O9-1) -> -0.19358807 | P53: =IF('20pdts2007'!P9=0,0,'20pdts2014'!P9/'20pdts2007'!P9-1) -> -0.009651614 | Q53: =IF('20pdts2007'!Q9=0,0,'20pdts2014'!Q9/'20pdts2007'!Q9-1) -> -0.00032921886
J54: D23 | K54: =IF('20pdts2007'!K10=0,0,'20pdts2014'!K10/'20pdts2007'!K10-1) -> -0.35078436 | L54: =IF('20pdts2007'!L10=0,0,'20pdts2014'!L10/'20pdts2007'!L10-1) -> -0.10775673 | M54: =IF('20pdts2007'!M10=0,0,'20pdts2014'!M10/'20pdts2007'!M10-1) -> 0.063510865 | N54: =IF('20pdts2007'!N10=0,0,'20pdts2014'!N10/'20pdts2007'!N10-1) -> 0.46791319 | O54: =IF('20pdts2007'!O10=0,0,'20pdts2014'!O10/'20pdts2007'!O10-1) -> 0.99227362 | P54: =IF('20pdts2007'!P10=0,0,'20pdts2014'!P10/'20pdts2007'!P10-1) -> 0.56302661 | Q54: =IF('20pdts2007'!Q10=0,0,'20pdts2014'!Q10/'20pdts2007'!Q10-1) -> -0.46753546
J55: E00 | K55: =IF('20pdts2007'!K11=0,0,'20pdts2014'!K11/'20pdts2007'!K11-1) -> -0.12019315 | L55: =IF('20pdts2007'!L11=0,0,'20pdts2014'!L11/'20pdts2007'!L11-1) -> -0.19887989 | M55: =IF('20pdts2007'!M11=0,0,'20pdts2014'!M11/'20pdts2007'!M11-1) -> -0.20293069 | N55: =IF('20pdts2007'!N11=0,0,'20pdts2014'!N11/'20pdts2007'!N11-1) -> -0.13464995 | O55: =IF('20pdts2007'!O11=0,0,'20pdts2014'!O11/'20pdts2007'!O11-1) -> 0.28595184 | P55: =IF('20pdts2007'!P11=0,0,'20pdts2014'!P11/'20pdts2007'!P11-1) -> -0.15615384 | Q55: =IF('20pdts2007'!Q11=0,0,'20pdts2014'!Q11/'20pdts2007'!Q11-1) -> 0.14457528
J56: F45 | K56: =IF('20pdts2007'!K12=0,0,'20pdts2014'!K12/'20pdts2007'!K12-1) -> -0.013263035 | L56: =IF('20pdts2007'!L12=0,0,'20pdts2014'!L12/'20pdts2007'!L12-1) -> 0.47469518 | M56: =IF('20pdts2007'!M12=0,0,'20pdts2014'!M12/'20pdts2007'!M12-1) -> 0.15456347 | N56: =IF('20pdts2007'!N12=0,0,'20pdts2014'!N12/'20pdts2007'!N12-1) -> -0.12376791 | O56: =IF('20pdts2007'!O12=0,0,'20pdts2014'!O12/'20pdts2007'!O12-1) -> 0.50803752 | P56: =IF('20pdts2007'!P12=0,0,'20pdts2014'!P12/'20pdts2007'!P12-1) -> 1.3820572 | Q56: =IF('20pdts2007'!Q12=0,0,'20pdts2014'!Q12/'20pdts2007'!Q12-1) -> -0.010325657
...

Sheet 60pdts2007
A1: beta-07 | B1: M1 | C1: M2 | D1: Q1 | E1: Q2 | F1: Q3 | G1: Q4 | H1: Q5 | J1: Elasticité-revenu 2007 | K1: M1 | L1: M2 | M1: Q1 | N1: Q2 | O1: Q3 | P1: Q4 | Q1: Q5 | S1: Elasticité-Prix 2007 | T1: M1 | U1: M2 | V1: Q1 | W1: Q2 | X1: Q3 | Y1: Q4 | Z1: Q5 | AB1: CB | AC1: M1 | AD1: M2 | AE1: Q1 | AF1: Q2 | AG1: Q3 | AH1: Q4 | AI1: Q5 | AJ1: CB-2007
A2: G01 | B2: 0.0187501 | C2: 0.0450117 | D2: 0.0989937 | E2: 0.0884269 | F2: 0.0734788 | G2: 0.054636 | H2: 0.0155113 | J2: G01 | K2: =IF(AC2=0,0,B2/AC2) -> 0.29891619 | L2: =IF(AD2=0,0,C2/AD2) -> 0.45614943 | M2: =IF(AE2=0,0,D2/AE2) -> 0.80344403 | N2: =IF(AF2=0,0,E2/AF2) -> 0.81076652 | O2: =IF(AG2=0,0,F2/AG2) -> 0.77423129 | P2: =IF(AH2=0,0,G2/AH2) -> 0.66247003 | Q2: =IF(AI2=0,0,H2/AI2) -> 0.32521352 | S2: G01 | T2: =IF(T52=0,0,((1-B2)*(K52/T52))-1) -> 0.034785149 | U2: =IF(U52=0,0,((1-C2)*(L52/U52))-1) -> -0.40851501 | V2: =IF(V52=0,0,((1-D2)*(M52/V52))-1) -> -0.84206145 | W2: =IF(W52=0,0,((1-E2)*(N52/W52))-1) -> -0.83376801 | X2: =IF(X52=0,0,((1-F2)*(O52/X52))-1) -> -0.80038434 | Y2: =IF(Y52=0,0,((1-G2)*(P52/Y52))-1) -> -0.65149517 | Z2: =IF(Z52=0,0,((1-H2)*(Q52/Z52))-1) -> 0.22125846 | AB2: G01 | AC2: 0.062726948 | AD2: 0.098677533 | AE2: 0.12321169 | AF2: 0.1090658 | AG2: 0.09490549 | AH2: 0.082473165 | AI2: 0.047695741 | AJ2: G01
A3: G02 | B3: 0.0206129 | C3: 0.0218548 | D3: 0.0292642 | E3: 0.0355814 | F3: 0.0289323 | G3: 0.0282661 | H3: 0.0168328 | J3: G02 | K3: =IF(AC3=0,0,B3/AC3) -> 0.59546444 | L3: =IF(AD3=0,0,C3/AD3) -> 0.80568398 | M3: =IF(AE3=0,0,D3/AE3) -> 1.0235349 | N3: =IF(AF3=0,0,E3/AF3) -> 1.1137533 | O3: =IF(AG3=0,0,F3/AG3) -> 0.84743054 | P3: =IF(AH3=0,0,G3/AH3) -> 0.80169306 | Q3: =IF(AI3=0,0,H3/AI3) -> 0.5405861 | S3: G02 | T3: =IF(T53=0,0,((1-B3)*(K53/T53))-1) -> 0.02350758 | U3: =IF(U53=0,0,((1-C3)*(L53/U53))-1) -> -0.54123327 | V3: =IF(V53=0,0,((1-D3)*(M53/V53))-1) -> -1.1117996 | W3: =IF(W53=0,0,((1-E3)*(N53/W53))-1) -> -1.1323451 | X3: =IF(X53=0,0,((1-F3)*(O53/X53))-1) -> -0.87971109 | Y3: =IF(Y53=0,0,((1-G3)*(P53/Y53))-1) -> -0.73656943 | Z3: =IF(Z53=0,0,((1-H3)*(Q53/Z53))-1) -> 0.30362711 | AB3: G02 | AC3: 0.034616509 | AD3: 0.027125772 | AE3: 0.028591305 | AF3: 0.031947289 | AG3: 0.034141205 | AH3: 0.035258008 | AI3: 0.031138056 | AJ3: G02
A4: G03 | B4: 0.0093069 | C4: 0.0324212 | D4: 0.0524832 | E4: 0.0519227 | F4: 0.0414569 | G4: 0.0338878 | H4: 0.0065255 | J4: G03 | K4: =IF(AC4=0,0,B4/AC4) -> 0.31269045 | L4: =IF(AD4=0,0,C4/AD4) -> 0.60997196 | M4: =IF(AE4=0,0,D4/AE4) -> 0.95972233 | N4: =IF(AF4=0,0,E4/AF4) -> 0.99678347 | O4: =IF(AG4=0,0,F4/AG4) -> 0.87863885 | P4: =IF(AH4=0,0,G4/AH4) -> 0.80661268 | Q4: =IF(AI4=0,0,H4/AI4) -> 0.25849365 | S4: G03 | T4: =IF(T54=0,0,((1-B4)*(K54/T54))-1) -> 0.41891883 | U4: =IF(U54=0,0,((1-C4)*(L54/U54))-1) -> -0.48697093 | V4: =IF(V54=0,0,((1-D4)*(M54/V54))-1) -> -1.0072317 | W4: =IF(W54=0,0,((1-E4)*(N54/W54))-1) -> -1.0106001 | X4: =IF(X54=0,0,((1-F4)*(O54/X54))-1) -> -0.90357254 | Y4: =IF(Y54=0,0,((1-G4)*(P54/Y54))-1) -> -0.75415213 | Z4: =IF(Z54=0,0,((1-H4)*(Q54/Z54))-1) -> 0.79853211 | AB4: G03 | AC4: 0.029763941 | AD4: 0.053151952 | AE4: 0.054685817 | AF4: 0.05209025 | AG4: 0.047183094 | AH4: 0.042012481 | AI4: 0.025244333 | AJ4: G03
A5: G04 | B5: 0.0564788 | C5: 0.1115151 | D5: 0.113481 | E5: 0.1308921 | F5: 0.1287152 | G5: 0.1138738 | H5: 0.0482654 | J5: G04 | K5: =IF(AC5=0,0,B5/AC5) -> 0.58936227 | L5: =IF(AD5=0,0,C5/AD5) -> 0.95359603 | M5: =IF(AE5=0,0,D5/AE5) -> 1.03195 | N5: =IF(AF5=0,0,E5/AF5) -> 1.147645 | O5: =IF(AG5=0,0,F5/AG5) -> 1.1527621 | P5: =IF(AH5=0,0,G5/AH5) -> 0.99849025 | Q5: =IF(AI5=0,0,H5/AI5) -> 0.53480866 | S5: G04 | T5: =IF(T55=0,0,((1-B5)*(K55/T55))-1) -> -0.39425179 | U5: =IF(U55=0,0,((1-C5)*(L55/U55))-1) -> -0.90215709 | V5: =IF(V55=0,0,((1-D5)*(M55/V55))-1) -> -1.0494462 | W5: =IF(W55=0,0,((1-E5)*(N55/W55))-1) -> -1.134034 | X5: =IF(X55=0,0,((1-F5)*(O55/X55))-1) -> -1.1407437 | Y5: =IF(Y55=0,0,((1-G5)*(P55/Y55))-1) -> -0.97872266 | Z5: =IF(Z55=0,0,((1-H5)*(Q55/Z55))-1) -> -0.2727138 | AB5: G04 | AC5: 0.095830362 | AD5: 0.11694166 | AE5: 0.10996754 | AF5: 0.11405277 | AG5: 0.11165808 | AH5: 0.11404598 | AI5: 0.090247978 | AJ5: G04
A6: G05 | B6: 0.0130662 | C6: 0.0109763 | D6: 0.0134419 | E6: 0.0095894 | F6: 0.0127218 | G6: 0.0118986 | H6: 0.0123905 | J6: G05 | K6: =IF(AC6=0,0,B6/AC6) -> 0.79672229 | L6: =IF(AD6=0,0,C6/AD6) -> 0.90588528 | M6: =IF(AE6=0,0,D6/AE6) -> 0.90924878 | N6: =IF(AF6=0,0,E6/AF6) -> 0.68396292 | O6: =IF(AG6=0,0,F6/AG6) -> 0.81859974 | P6: =IF(AH6=0,0,G6/AH6) -> 0.79912442 | Q6: =IF(AI6=0,0,H6/AI6) -> 0.80723397 | S6: G05 | T6: =IF(T56=0,0,((1-B6)*(K56/T56))-1) -> 0.53493309 | U6: =IF(U56=0,0,((1-C6)*(L56/U56))-1) -> -0.29869044 | V6: =IF(V56=0,0,((1-D6)*(M56/V56))-1) -> -1.0853139 | W6: =IF(W56=0,0,((1-E6)*(N56/W56))-1) -> -0.73997014 | X6: =IF(X56=0,0,((1-F6)*(O56/X56))-1) -> -0.88314248 | Y6: =IF(Y56=0,0,((1-G6)*(P56/Y56))-1) -> -0.63121097 | Z6: =IF(Z56=0,0,((1-H6)*(Q56/Z56))-1) -> 0.92646252 | AB6: G05 | AC6: 0.016399943 | AD6: 0.012116656 | AE6: 0.014783523 | AF6: 0.014020351 | AG6: 0.015540928 | AH6: 0.014889546 | AI6: 0.015349329 | AJ6: G05
A7: G06 | B7: 0.0099108 | C7: 0.0340422 | D7: 0.0613363 | E7: 0.0552145 | F7: 0.0480111 | G7: 0.0388069 | H7: 0.0078959 | J7: G06 | K7: =IF(AC7=0,0,B7/AC7) -> 0.29135356 | L7: =IF(AD7=0,0,C7/AD7) -> 0.66763854 | M7: =IF(AE7=0,0,D7/AE7) -> 1.0434813 | N7: =IF(AF7=0,0,E7/AF7) -> 0.97172687 | O7: =IF(AG7=0,0,F7/AG7) -> 0.95743946 | P7: =IF(AH7=0,0,G7/AH7) -> 0.87822895 | Q7: =IF(AI7=0,0,H7/AI7) -> 0.29702477 | S7: G06 | T7: =IF(T57=0,0,((1-B7)*(K57/T57))-1) -> 0.34697665 | U7: =IF(U57=0,0,((1-C7)*(L57/U57))-1) -> -0.53778923 | V7: =IF(V57=0,0,((1-D7)*(M57/V57))-1) -> -1.0826533 | W7: =IF(W57=0,0,((1-E7)*(N57/W57))-1) -> -0.98575698 | X7: =IF(X57=0,0,((1-F7)*(O57/X57))-1) -> -0.97808213 | Y7: =IF(Y57=0,0,((1-G7)*(P57/Y57))-1) -> -0.82713245 | Z7: =IF(Z57=0,0,((1-H7)*(Q57/Z57))-1) -> 0.70441026 | AB7: G06 | AC7: 0.034016403 | AD7: 0.050988968 | AE7: 0.058780448 | AF7: 0.056821008 | AG7: 0.050145312 | AH7: 0.04418768 | AI7: 0.026583305 | AJ7: G06
A8: G07 | B8: 0.003922 | C8: 0.011604 | D8: 0.0172521 | E8: 0.0196611 | F8: 0.0171507 | G8: 0.0121642 | H8: 0.0034879 | J8: G07 | K8: =IF(AC8=0,0,B8/AC8) -> 0.30043915 | L8: =IF(AD8=0,0,C8/AD8) -> 0.64974666 | M8: =IF(AE8=0,0,D8/AE8) -> 0.85168512 | N8: =IF(AF8=0,0,E8/AF8) -> 0.91655754 | O8: =IF(AG8=0,0,F8/AG8) -> 0.91605225 | P8: =IF(AH8=0,0,G8/AH8) -> 0.72899064 | Q8: =IF(AI8=0,0,H8/AI8) -> 0.35605862 | S8: G07 | T8: =IF(T58=0,0,((1-B8)*(K58/T58))-1) -> 1.3886353 | U8: =IF(U58=0,0,((1-C8)*(L58/U58))-1) -> -0.24141939 | V8: =IF(V58=0,0,((1-D8)*(M58/V58))-1) -> -0.9813548 | W8: =IF(W58=0,0,((1-E8)*(N58/W58))-1) -> -0.95247102 | X8: =IF(X58=0,0,((1-F8)*(O58/X58))-1) -> -0.968923 | Y8: =IF(Y58=0,0,((1-G8)*(P58/Y58))-1) -> -0.58036338 | Z8: =IF(Z58=0,0,((1-H8)*(Q58/Z58))-1) -> 2.3865239 | AB8: G07 | AC8: 0.013054224 | AD8: 0.017859269 | AE8: 0.02025643 | AF8: 0.021451026 | AG8: 0.018722404 | AH8: 0.01668636 | AI8: 0.0097958589 | AJ8: G07
A9: G08 | B9: 0.018127 | C9: 0.0353989 | D9: 0.028647 | E9: 0.0380489 | F9: 0.0323319 | G9: 0.0325771 | H9: 0.0155415 | J9: G08 | K9: =IF(AC9=0,0,B9/AC9) -> 0.75371663 | L9: =IF(AD9=0,0,C9/AD9) -> 1.1722626 | M9: =IF(AE9=0,0,D9/AE9) -> 1.4667909 | N9: =IF(AF9=0,0,E9/AF9) -> 1.515512 | O9: =IF(AG9=0,0,F9/AG9) -> 1.2436673 | P9: =IF(AH9=0,0,G9/AH9) -> 1.1115554 | Q9: =IF(AI9=0,0,H9/AI9) -> 0.60912714 | S9: G08 | T9: =IF(T59=0,0,((1-B9)*(K59/T59))-1) -> 0.14703017 | U9: =IF(U59=0,0,((1-C9)*(L59/U59))-1) -> -0.92813828 | V9: =IF(V59=0,0,((1-D9)*(M59/V59))-1) -> -1.5837274 | W9: =IF(W59=0,0,((1-E9)*(N59/W59))-1) -> -1.5246309 | X9: =IF(X59=0,0,((1-F9)*(O59/X59))-1) -> -1.2722533 | Y9: =IF(Y59=0,0,((1-G9)*(P59/Y59))-1) -> -1.023211 | Z9: =IF(Z59=0,0,((1-H9)*(Q59/Z59))-1) -> 0.42588639 | AB9: G08 | AC9: 0.024050153 | AD9: 0.030197072 | AE9: 0.019530391 | AF9: 0.025106301 | AG9: 0.025997227 | AH9: 0.02930767 | AI9: 0.025514378 | AJ9: G08
A10: G09 | B10: 0.0050681 | C10: 0.0120172 | D10: 0.0294931 | E10: 0.0237853 | F10: 0.0140136 | G10: 0.013014 | H10: 0.0050898 | J10: G09 | K10: =IF(AC10=0,0,B10/AC10) -> 0.40796649 | L10: =IF(AD10=0,0,C10/AD10) -> 0.44341527 | M10: =IF(AE10=0,0,D10/AE10) -> 0.86699336 | N10: =IF(AF10=0,0,E10/AF10) -> 0.88231311 | O10: =IF(AG10=0,0,F10/AG10) -> 0.63321431 | P10: =IF(AH10=0,0,G10/AH10) -> 0.73034553 | Q10: =IF(AI10=0,0,H10/AI10) -> 0.50918648 | S10: G09 | T10: =IF(T60=0,0,((1-B10)*(K60/T60))-1) -> 1.3647913 | U10: =IF(U60=0,0,((1-C10)*(L60/U60))-1) -> -0.17846266 | V10: =IF(V60=0,0,((1-D10)*(M60/V60))-1) -> -0.94566499 | W10: =IF(W60=0,0,((1-E10)*(N60/W60))-1) -> -0.91226993 | X10: =IF(X60=0,0,((1-F10)*(O60/X60))-1) -> -0.6820038 | Y10: =IF(Y60=0,0,((1-G10)*(P60/Y60))-1) -> -0.59170928 | Z10: =IF(Z60=0,0,((1-H10)*(Q60/Z60))-1) -> 2.1738799 | AB10: G09 | AC10: 0.012422834 | AD10: 0.027101457 | AE10: 0.034017677 | AF10: 0.02695789 | AG10: 0.022130896 | AH10: 0.017818963 | AI10: 0.0099959449 | AJ10: G09
A11: G10 | B11: 0.0007615 | C11: 0.000136 | D11: 0.0002725 | E11: 0.000163 | F11: 0.0003405 | G11: 0.0002334 | H11: 0.0007457 | J11: G10 | K11: =IF(AC11=0,0,B11/AC11) -> 1.6492917 | L11: =IF(AD11=0,0,C11/AD11) -> 0.94757217 | M11: =IF(AE11=0,0,D11/AE11) -> 3.0435244 | N11: =IF(AF11=0,0,E11/AF11) -> 0.98947822 | O11: =IF(AG11=0,0,F11/AG11) -> 1.5380999 | P11: =IF(AH11=0,0,G11/AH11) -> 0.86530395 | Q11: =IF(AI11=0,0,H11/AI11) -> 1.3847732 | S11: G10 | T11: =IF(T61=0,0,((1-B11)*(K61/T61))-1) -> 46.336445 | U11: =IF(U61=0,0,((1-C11)*(L61/U61))-1) -> 50.963266 | V11: =IF(V61=0,0,((1-D11)*(M61/V61))-1) -> -32.298107 | W11: =IF(W61=0,0,((1-E11)*(N61/W61))-1) -> -5.5408237 | X11: =IF(X61=0,0,((1-F11)*(O61/X61))-1) -> -5.9620374 | Y11: =IF(Y61=0,0,((1-G11)*(P61/Y61))-1) -> 8.6465939 | Z11: =IF(Z61=0,0,((1-H11)*(Q61/Z61))-1) -> 48.684165 | AB11: G10 | AC11: 0.00046171336 | AD11: 0.00014352469 | AE11: 8.9534358e-05 | AF11: 0.00016473329 | AG11: 0.00022137704 | AH11: 0.00026973181 | AI11: 0.00053849973 | AJ11: G10
A12: G11 | B12: 0.0033931 | C12: 0.0111897 | D12: 0.022242 | E12: 0.0193331 | F12: 0.0128523 | G12: 0.0119997 | H12: 0.0025898 | J12: G11 | K12: =IF(AC12=0,0,B12/AC12) -> 0.28828687 | L12: =IF(AD12=0,0,C12/AD12) -> 0.49642423 | M12: =IF(AE12=0,0,D12/AE12) -> 0.85594296 | N12: =IF(AF12=0,0,E12/AF12) -> 0.86300563 | O12: =IF(AG12=0,0,F12/AG12) -> 0.67596322 | P12: =IF(AH12=0,0,G12/AH12) -> 0.70618906 | Q12: =IF(AI12=0,0,H12/AI12) -> 0.26856503 | S12: G11 | T12: =IF(T62=0,0,((1-B12)*(K62/T62))-1) -> 1.5867304 | U12: =IF(U62=0,0,((1-C12)*(L62/U62))-1) -> -0.17517982 | V12: =IF(V62=0,0,((1-D12)*(M62/V62))-1) -> -0.95772975 | W12: =IF(W62=0,0,((1-E12)*(N62/W62))-1) -> -0.89848435 | X12: =IF(X62=0,0,((1-F12)*(O62/X62))-1) -> -0.73099271 | Y12: =IF(Y62=0,0,((1-G12)*(P62/Y62))-1) -> -0.56050034 | Z12: =IF(Z62=0,0,((1-H12)*(Q62/Z62))-1) -> 2.520365 | AB12: G11 | AC12: 0.011769873 | AD12: 0.0225406 | AE12: 0.025985376 | AF12: 0.022402055 | AG12: 0.019013313 | AH12: 0.016992192 | AI12: 0.0096431021 | AJ12: G11
A13: G12 | B13: 0.0028999 | C13: 0.0081623 | D13: 0.0158173 | E13: 0.0166396 | F13: 0.0108618 | G13: 0.0077995 | H13: 0.0024197 | J13: G12 | K13: =IF(AC13=0,0,B13/AC13) -> 0.35487166 | L13: =IF(AD13=0,0,C13/AD13) -> 0.53339468 | M13: =IF(AE13=0,0,D13/AE13) -> 0.89405974 | N13: =IF(AF13=0,0,E13/AF13) -> 1.1195783 | O13: =IF(AG13=0,0,F13/AG13) -> 0.82939494 | P13: =IF(AH13=0,0,G13/AH13) -> 0.66785942 | Q13: =IF(AI13=0,0,H13/AI13) -> 0.35760701 | S13: G12 | T13: =IF(T63=0,0,((1-B13)*(K63/T63))-1) -> 2.3487078 | U13: =IF(U63=0,0,((1-C13)*(L63/U63))-1) -> -0.054237699 | V13: =IF(V63=0,0,((1-D13)*(M63/V63))-1) -> -1.0414845 | W13: =IF(W63=0,0,((1-E13)*(N63/W63))-1) -> -1.1672071 | X13: =IF(X63=0,0,((1-F13)*(O63/X63))-1) -> -0.90524481 | Y13: =IF(Y63=0,0,((1-G13)*(P63/Y63))-1) -> -0.45241602 | Z13: =IF(Z63=0,0,((1-H13)*(Q63/Z63))-1) -> 3.6188627 | AB13: G12 | AC13: 0.0081716866 | AD13: 0.015302552 | AE13: 0.017691547 | AF13: 0.014862382 | AG13: 0.013096053 | AH13: 0.011678356 | AI13: 0.0067663662 | AJ13: G12
... A49: G76 | B49: 0.0499702 | C49: 0.0113828 | D49: 0.020195 | E49: 0.0213084 | F49: 0.0256024 | G49: 0.0264869 | H49: 0.0520874 | J49: G76 | K49: =IF(AC49=0,0,B49/AC49) -> 1.5290113 | L49: =IF(AD49=0,0,C49/AD49) -> 0.92870646 | M49: =IF(AE49=0,0,D49/AE49) -> 0.92889775 | N49: =IF(AF49=0,0,E49/AF49) -> 1.063885 | O49: =IF(AG49=0,0,F49/AG49) -> 1.1742778 | P49: =IF(AH49=0,0,G49/AH49) -> 1.3184659 | Q49: =IF(AI49=0,0,H49/AI49) -> 1.5813436 | S49: G76 | T49: =IF(T99=0,0,((1-B49)*(K99/T99))-1) -> -0.85803831 | U49: =IF(U99=0,0,((1-C49)*(L99/U99))-1) -> -0.32848301 | V49: =IF(V99=0,0,((1-D49)*(M99/V99))-1) -> -1.0484127 | W49: =IF(W99=0,0,((1-E49)*(N99/W99))-1) -> -1.0991697 | X49: =IF(X99=0,0,((1-F49)*(O99/X99))-1) -> -1.2136001 | Y49: =IF(Y99=0,0,((1-G49)*(P99/Y99))-1) -> -1.1856692 | Z49: =IF(Z99=0,0,((1-H49)*(Q99/Z99))-1) -> -0.77456884 | AB49: G76 | AC49: 0.03268138 | AD49: 0.012256618 | AE49: 0.021740821 | AF49: 0.020028856 | AG49: 0.021802677 | AH49: 0.020089182 | AI49: 0.032938698 | AJ49: G76
AB50: G81 | AC50: 0.0014336681 | AD50: 0.0010965798 | AE50: 0.00015416122 | AF50: 0.00034057245 | AG50: 0.0002577031 | AH50: 0.00075045919 | AI50: 0.002323807 | AJ50: G81
A51: alpha-07 | B51: M1 | C51: M2 | D51: Q1 | E51: Q2 | F51: Q3 | G51: Q4 | H51: Q5 | J51: CMIN | K51: M1 | L51: M2 | M51: Q1 | N51: Q2 | O51: Q3 | P51: Q4 | Q51: Q5 | S51: Cmoyen | T51: M1 | U51: M2 | V51: Q1 | W51: Q2 | X51: Q3 | Y51: Q4 | Z51: Q5 | AB51: G82 | AC51: 9.9706907e-05 | AD51: 3.6940122e-05 | AE51: 6.5290075e-05 | AF51: 2.0746227e-05 | AG51: 4.5520205e-05 | AH51: 2.6296905e-05 | AI51: 0.00013158971 | AJ51: G82
A52: G01 | B52: 2885.613 | C52: 2338.163 | D52: 587.9116 | E52: 725.1099 | F52: 936.6098 | G52: 1528.812 | H52: 3314.734 | J52: G01 | K52: 4340.487 | L52: 2662.8149 | M52: 524.3086 | N52: 698.76257 | O52: 893.78544 | P52: 1669.7508 | Q52: 6093.6653 | S52: G01 | T52: =Cmoyen!J3 -> 4115.9292 | U52: =Cmoyen!K3 -> 4299.2758 | V52: =Cmoyen!Q26 -> 2991.0707 | W52: =Cmoyen!R26 -> 3831.8327 | X52: =Cmoyen!S26 -> 4148.5281 | Y52: =Cmoyen!T26 -> 4529.4128 | Z52: =Cmoyen!U26 -> 4912.2646 | AB52: G83 | AC52: 0.00034034315 | AD52: 0.00017443126 | AE52: 1.3153813e-05 | AF52: 0.00016301588 | AG52: 8.7002328e-05 | AH52: 0.00017821566 | AI52: 0.00047237116 | AJ52: G83
A53: G02 | B53: 918.869 | C53: 229.6517 | D53: -16.33402 | E53: -127.6788 | F53: 227.6906 | G53: 383.9966 | H53: 1473.327 | J53: G02 | K53: 2373.743 | L53: 554.30361 | M53: -79.937018 | N53: -154.02613 | O53: 184.86624 | P53: 524.93537 | Q53: 4252.2583 | S53: G02 | T53: =Cmoyen!J4 -> 2271.4177 | U53: =Cmoyen!K4 -> 1181.8412 | V53: =Cmoyen!Q27 -> 694.07871 | W53: =Cmoyen!R27 -> 1122.4111 | X53: =Cmoyen!S27 -> 1492.3873 | Y53: =Cmoyen!T27 -> 1936.3641 | Z53: =Cmoyen!U27 -> 3206.9607 | AB53: G84 | AC53: 0.00010663388 | AD53: 0.00018122824 | AE53: 0.00014067579 | AF53: 0.00012612607 | AG53: 0.0001508274 | AH53: 0.00010369154 | AI53: 0.00013261734 | AJ53: G84
A54: G03 | B54: 1342.32 | C54: 903.2166 | D54: 53.47076 | E54: 5.885601 | F54: 250.3053 | G54: 446.2077 | H54: 1927.888 | J54: G03 | K54: 2797.194 | L54: 1227.8685 | M54: -10.132238 | N54: -20.461724 | O54: 207.48094 | P54: 587.14647 | Q54: 4706.8193 | S54: G03 | T54: =Cmoyen!J5 -> 1953.0087 | U54: =Cmoyen!K5 -> 2315.7743 | V54: =Cmoyen!Q28 -> 1327.5456 | W54: =Cmoyen!R28 -> 1830.0981 | X54: =Cmoyen!S28 -> 2062.477 | Y54: =Cmoyen!T28 -> 2307.3186 | Z54: =Cmoyen!U28 -> 2599.9564 | AB54: G85 | AC54: 0.017585505 | AD54: 0.019711668 | AE54: 0.0093725893 | AF54: 0.0092270792 | AG54: 0.011174943 | AH54: 0.016665828 | AI54: 0.024507278 | AJ54: G85
A55: G04 | B55: 2582.113 | C55: 236.4291 | D55: -85.29351 | E55: -591.6195 | F55: -745.6029 | G55: 9.455423 | H55: 4323.861 | J55: G04 | K55: 4036.987 | L55: 561.08101 | M55: -148.89651 | N55: -617.96683 | O55: -788.42726 | P55: 150.39419 | Q55: 7102.7923 | S55: G04 | T55: =Cmoyen!J6 -> 6288.0628 | U55: =Cmoyen!K6 -> 5095.0243 | V55: =Cmoyen!Q29 -> 2669.5572 | W55: =Cmoyen!R29 -> 4007.041 | X55: =Cmoyen!S29 -> 4880.8206 | Y55: =Cmoyen!T29 -> 6263.3868 | Z55: =Cmoyen!U29 -> 9294.7911 | AB55: G86 | AC55: 2.7507817e-05 | AD55: 5.0484834e-05 | AE55: 0 | AF55: 4.4652476e-05 | AG55: 4.2550045e-05 | AH55: 4.1963147e-05 | AI55: 3.1252689e-05 | AJ55: G86
